Workbook

Sheet Leia-me
B2: Controle de Qualidade ANEC 73 x Pool — Motor de Calculo
B4: Estrutura da planilha
B5: Esta planilha tem duas camadas, ligadas por formula (nao ha nenhum valor digitado manualmente nos resultados):
B7: 1) ABAS NO LAYOUT ORIGINAL (azul-marinho na aba): MEDIA POOL, PROTEINA, UMIDADE, FIBRA, uma aba por
B8: cliente e Base Cobranca. Aparencia igual a planilha anterior, mas cada celula agora e formula — nada
B9: e mais digitado a mao, entao nao ha risco de referencia errada ou valor esquecido de um mes pro outro.
B11: 2) MOTOR DE CALCULO (amarelo/azul-claro na aba): DADOS, Parametros_ANEC73, Clientes, Media_Cliente_Mes,
B12: Media_Pool_Mes, Desconto_Cliente_Mes, Acerto_Detalhado, Resumo_Cliente_Mes. E onde a regra ANEC 73 x
B13: pool e calculada de fato, uma unica vez, para depois alimentar as abas do item 1. Se um dia quiser
B14: auditar um numero especifico, comece pela aba Desconto_Cliente_Mes (fica claro linha a linha o porque
B15: de cada desconto).
B17: Como usar todo mes
... B44: corrigido para nao gerar desconto fantasma sobre cliente que nao embarcou.

Sheet MEDIA POOL
A1: MEDIA POOL 48 (corrigida — lista de clientes ajustada, sem duplicidade)
A3: Jan | B3: Amaggi | C3: Brejeiro | D3: Caramuru | E3: Cargill | F3: Cofco | G3: 3Tentos | H3: Bunge | I3: ADM | J3: Aliança | K3: Olfar | L3: Novo06 | M3: Novo07 | N3: Media Pool
A4: Volume | B4: =IFERROR(SUMIFS(Media_Cliente_Mes!$C$2:$C$145,Media_Cliente_Mes!$A$2:$A$145,$B$3,Media_Cliente_Mes!$B$2:$B$145,$A3),0) -> 0 | C4: =IFERROR(SUMIFS(Media_Cliente_Mes!$C$2:$C$145,Media_Cliente_Mes!$A$2:$A$145,$C$3,Media_Cliente_Mes!$B$2:$B$145,$A3),0) -> 39842.6 | D4: =IFERROR(SUMIFS(Media_Cliente_Mes!$C$2:$C$145,Media_Cliente_Mes!$A$2:$A$145,$D$3,Media_Cliente_Mes!$B$2:$B$145,$A3),0) -> 18891.74 | E4: =IFERROR(SUMIFS(Media_Cliente_Mes!$C$2:$C$145,Media_Cliente_Mes!$A$2:$A$145,$E$3,Media_Cliente_Mes!$B$2:$B$145,$A3),0) -> 26334.33 | F4: =IFERROR(SUMIFS(Media_Cliente_Mes!$C$2:$C$145,Media_Cliente_Mes!$A$2:$A$145,$F$3,Media_Cliente_Mes!$B$2:$B$145,$A3),0) -> 58133.28 | G4: =IFERROR(SUMIFS(Media_Cliente_Mes!$C$2:$C$145,Media_Cliente_Mes!$A$2:$A$145,$G$3,Media_Cliente_Mes!$B$2:$B$145,$A3),0) -> 48560.63 | H4: =IFERROR(SUMIFS(Media_Cliente_Mes!$C$2:$C$145,Media_Cliente_Mes!$A$2:$A$145,$H$3,Media_Cliente_Mes!$B$2:$B$145,$A3),0) -> 72053.69 | I4: =IFERROR(SUMIFS(Media_Cliente_Mes!$C$2:$C$145,Media_Cliente_Mes!$A$2:$A$145,$I$3,Media_Cliente_Mes!$B$2:$B$145,$A3),0) -> 0 | J4: =IFERROR(SUMIFS(Media_Cliente_Mes!$C$2:$C$145,Media_Cliente_Mes!$A$2:$A$145,$J$3,Media_Cliente_Mes!$B$2:$B$145,$A3),0) -> 0 | K4: =IFERROR(SUMIFS(Media_Cliente_Mes!$C$2:$C$145,Media_Cliente_Mes!$A$2:$A$145,$K$3,Media_Cliente_Mes!$B$2:$B$145,$A3),0) -> 0 | L4: =IFERROR(SUMIFS(Media_Cliente_Mes!$C$2:$C$145,Media_Cliente_Mes!$A$2:$A$145,$L$3,Media_Cliente_Mes!$B$2:$B$145,$A3),0) -> 0 | M4: =IFERROR(SUMIFS(Media_Cliente_Mes!$C$2:$C$145,Media_Cliente_Mes!$A$2:$A$145,$M$3,Media_Cliente_Mes!$B$2:$B$145,$A3),0) -> 0 | N4: =SUM(B4:M4) -> 263816.27
A5: Proteina Bruta (%) | B5: =IFERROR(SUMIFS(Media_Cliente_Mes!$D$2:$D$145,Media_Cliente_Mes!$A$2:$A$145,$B$3,Media_Cliente_Mes!$B$2:$B$145,$A3),0) -> 0 | C5: =IFERROR(SUMIFS(Media_Cliente_Mes!$D$2:$D$145,Media_Cliente_Mes!$A$2:$A$145,$C$3,Media_Cliente_Mes!$B$2:$B$145,$A3),0) -> 48.328751 | D5: =IFERROR(SUMIFS(Media_Cliente_Mes!$D$2:$D$145,Media_Cliente_Mes!$A$2:$A$145,$D$3,Media_Cliente_Mes!$B$2:$B$145,$A3),0) -> 47.985938 | E5: =IFERROR(SUMIFS(Media_Cliente_Mes!$D$2:$D$145,Media_Cliente_Mes!$A$2:$A$145,$E$3,Media_Cliente_Mes!$B$2:$B$145,$A3),0) -> 47.805872 | F5: =IFERROR(SUMIFS(Media_Cliente_Mes!$D$2:$D$145,Media_Cliente_Mes!$A$2:$A$145,$F$3,Media_Cliente_Mes!$B$2:$B$145,$A3),0) -> 47.760801 | G5: =IFERROR(SUMIFS(Media_Cliente_Mes!$D$2:$D$145,Media_Cliente_Mes!$A$2:$A$145,$G$3,Media_Cliente_Mes!$B$2:$B$145,$A3),0) -> 47.568335 | H5: =IFERROR(SUMIFS(Media_Cliente_Mes!$D$2:$D$145,Media_Cliente_Mes!$A$2:$A$145,$H$3,Media_Cliente_Mes!$B$2:$B$145,$A3),0) -> 47.701003 | I5: =IFERROR(SUMIFS(Media_Cliente_Mes!$D$2:$D$145,Media_Cliente_Mes!$A$2:$A$145,$I$3,Media_Cliente_Mes!$B$2:$B$145,$A3),0) -> 0 | J5: =IFERROR(SUMIFS(Media_Cliente_Mes!$D$2:$D$145,Media_Cliente_Mes!$A$2:$A$145,$J$3,Media_Cliente_Mes!$B$2:$B$145,$A3),0) -> 0 | K5: =IFERROR(SUMIFS(Media_Cliente_Mes!$D$2:$D$145,Media_Cliente_Mes!$A$2:$A$145,$K$3,Media_Cliente_Mes!$B$2:$B$145,$A3),0) -> 0 | L5: =IFERROR(SUMIFS(Media_Cliente_Mes!$D$2:$D$145,Media_Cliente_Mes!$A$2:$A$145,$L$3,Media_Cliente_Mes!$B$2:$B$145,$A3),0) -> 0 | M5: =IFERROR(SUMIFS(Media_Cliente_Mes!$D$2:$D$145,Media_Cliente_Mes!$A$2:$A$145,$M$3,Media_Cliente_Mes!$B$2:$B$145,$A3),0) -> 0 | N5: =IFERROR(SUMPRODUCT(B4:M4,B5:M5)/SUM(B4:M4),0) -> 47.815437
A6: Umidade (%) | B6: =IFERROR(SUMIFS(Media_Cliente_Mes!$E$2:$E$145,Media_Cliente_Mes!$A$2:$A$145,$B$3,Media_Cliente_Mes!$B$2:$B$145,$A3),0) -> 0 | C6: =IFERROR(SUMIFS(Media_Cliente_Mes!$E$2:$E$145,Media_Cliente_Mes!$A$2:$A$145,$C$3,Media_Cliente_Mes!$B$2:$B$145,$A3),0) -> 11.618067 | D6: =IFERROR(SUMIFS(Media_Cliente_Mes!$E$2:$E$145,Media_Cliente_Mes!$A$2:$A$145,$D$3,Media_Cliente_Mes!$B$2:$B$145,$A3),0) -> 12.416467 | E6: =IFERROR(SUMIFS(Media_Cliente_Mes!$E$2:$E$145,Media_Cliente_Mes!$A$2:$A$145,$E$3,Media_Cliente_Mes!$B$2:$B$145,$A3),0) -> 12.110898 | F6: =IFERROR(SUMIFS(Media_Cliente_Mes!$E$2:$E$145,Media_Cliente_Mes!$A$2:$A$145,$F$3,Media_Cliente_Mes!$B$2:$B$145,$A3),0) -> 12.0884 | G6: =IFERROR(SUMIFS(Media_Cliente_Mes!$E$2:$E$145,Media_Cliente_Mes!$A$2:$A$145,$G$3,Media_Cliente_Mes!$B$2:$B$145,$A3),0) -> 12.20746 | H6: =IFERROR(SUMIFS(Media_Cliente_Mes!$E$2:$E$145,Media_Cliente_Mes!$A$2:$A$145,$H$3,Media_Cliente_Mes!$B$2:$B$145,$A3),0) -> 12.131259 | I6: =IFERROR(SUMIFS(Media_Cliente_Mes!$E$2:$E$145,Media_Cliente_Mes!$A$2:$A$145,$I$3,Media_Cliente_Mes!$B$2:$B$145,$A3),0) -> 0 | J6: =IFERROR(SUMIFS(Media_Cliente_Mes!$E$2:$E$145,Media_Cliente_Mes!$A$2:$A$145,$J$3,Media_Cliente_Mes!$B$2:$B$145,$A3),0) -> 0 | K6: =IFERROR(SUMIFS(Media_Cliente_Mes!$E$2:$E$145,Media_Cliente_Mes!$A$2:$A$145,$K$3,Media_Cliente_Mes!$B$2:$B$145,$A3),0) -> 0 | L6: =IFERROR(SUMIFS(Media_Cliente_Mes!$E$2:$E$145,Media_Cliente_Mes!$A$2:$A$145,$L$3,Media_Cliente_Mes!$B$2:$B$145,$A3),0) -> 0 | M6: =IFERROR(SUMIFS(Media_Cliente_Mes!$E$2:$E$145,Media_Cliente_Mes!$A$2:$A$145,$M$3,Media_Cliente_Mes!$B$2:$B$145,$A3),0) -> 0 | N6: =IFERROR(SUMPRODUCT(B4:M4,B6:M6)/SUM(B4:M4),0) -> 12.076728
A7: Fibra (%) | B7: =IFERROR(SUMIFS(Media_Cliente_Mes!$F$2:$F$145,Media_Cliente_Mes!$A$2:$A$145,$B$3,Media_Cliente_Mes!$B$2:$B$145,$A3),0) -> 0 | C7: =IFERROR(SUMIFS(Media_Cliente_Mes!$F$2:$F$145,Media_Cliente_Mes!$A$2:$A$145,$C$3,Media_Cliente_Mes!$B$2:$B$145,$A3),0) -> 3.1245148 | D7: =IFERROR(SUMIFS(Media_Cliente_Mes!$F$2:$F$145,Media_Cliente_Mes!$A$2:$A$145,$D$3,Media_Cliente_Mes!$B$2:$B$145,$A3),0) -> 3.3765405 | E7: =IFERROR(SUMIFS(Media_Cliente_Mes!$F$2:$F$145,Media_Cliente_Mes!$A$2:$A$145,$E$3,Media_Cliente_Mes!$B$2:$B$145,$A3),0) -> 3.5983696 | F7: =IFERROR(SUMIFS(Media_Cliente_Mes!$F$2:$F$145,Media_Cliente_Mes!$A$2:$A$145,$F$3,Media_Cliente_Mes!$B$2:$B$145,$A3),0) -> 3.5153253 | G7: =IFERROR(SUMIFS(Media_Cliente_Mes!$F$2:$F$145,Media_Cliente_Mes!$A$2:$A$145,$G$3,Media_Cliente_Mes!$B$2:$B$145,$A3),0) -> 3.6238922 | H7: =IFERROR(SUMIFS(Media_Cliente_Mes!$F$2:$F$145,Media_Cliente_Mes!$A$2:$A$145,$H$3,Media_Cliente_Mes!$B$2:$B$145,$A3),0) -> 3.6723482 | I7: =IFERROR(SUMIFS(Media_Cliente_Mes!$F$2:$F$145,Media_Cliente_Mes!$A$2:$A$145,$I$3,Media_Cliente_Mes!$B$2:$B$145,$A3),0) -> 0 | J7: =IFERROR(SUMIFS(Media_Cliente_Mes!$F$2:$F$145,Media_Cliente_Mes!$A$2:$A$145,$J$3,Media_Cliente_Mes!$B$2:$B$145,$A3),0) -> 0 | K7: =IFERROR(SUMIFS(Media_Cliente_Mes!$F$2:$F$145,Media_Cliente_Mes!$A$2:$A$145,$K$3,Media_Cliente_Mes!$B$2:$B$145,$A3),0) -> 0 | L7: =IFERROR(SUMIFS(Media_Cliente_Mes!$F$2:$F$145,Media_Cliente_Mes!$A$2:$A$145,$L$3,Media_Cliente_Mes!$B$2:$B$145,$A3),0) -> 0 | M7: =IFERROR(SUMIFS(Media_Cliente_Mes!$F$2:$F$145,Media_Cliente_Mes!$A$2:$A$145,$M$3,Media_Cliente_Mes!$B$2:$B$145,$A3),0) -> 0 | N7: =IFERROR(SUMPRODUCT(B4:M4,B7:M7)/SUM(B4:M4),0) -> 3.5175249
A8: Oleo (%) | B8: =IFERROR(SUMIFS(Media_Cliente_Mes!$G$2:$G$145,Media_Cliente_Mes!$A$2:$A$145,$B$3,Media_Cliente_Mes!$B$2:$B$145,$A3),0) -> 0 | C8: =IFERROR(SUMIFS(Media_Cliente_Mes!$G$2:$G$145,Media_Cliente_Mes!$A$2:$A$145,$C$3,Media_Cliente_Mes!$B$2:$B$145,$A3),0) -> 1.4035429 | D8: =IFERROR(SUMIFS(Media_Cliente_Mes!$G$2:$G$145,Media_Cliente_Mes!$A$2:$A$145,$D$3,Media_Cliente_Mes!$B$2:$B$145,$A3),0) -> 1.2043202 | E8: =IFERROR(SUMIFS(Media_Cliente_Mes!$G$2:$G$145,Media_Cliente_Mes!$A$2:$A$145,$E$3,Media_Cliente_Mes!$B$2:$B$145,$A3),0) -> 1.7467669 | F8: =IFERROR(SUMIFS(Media_Cliente_Mes!$G$2:$G$145,Media_Cliente_Mes!$A$2:$A$145,$F$3,Media_Cliente_Mes!$B$2:$B$145,$A3),0) -> 1.5928967 | G8: =IFERROR(SUMIFS(Media_Cliente_Mes!$G$2:$G$145,Media_Cliente_Mes!$A$2:$A$145,$G$3,Media_Cliente_Mes!$B$2:$B$145,$A3),0) -> 1.6171417 | H8: =IFERROR(SUMIFS(Media_Cliente_Mes!$G$2:$G$145,Media_Cliente_Mes!$A$2:$A$145,$H$3,Media_Cliente_Mes!$B$2:$B$145,$A3),0) -> 1.6404812 | I8: =IFERROR(SUMIFS(Media_Cliente_Mes!$G$2:$G$145,Media_Cliente_Mes!$A$2:$A$145,$I$3,Media_Cliente_Mes!$B$2:$B$145,$A3),0) -> 0 | J8: =IFERROR(SUMIFS(Media_Cliente_Mes!$G$2:$G$145,Media_Cliente_Mes!$A$2:$A$145,$J$3,Media_Cliente_Mes!$B$2:$B$145,$A3),0) -> 0 | K8: =IFERROR(SUMIFS(Media_Cliente_Mes!$G$2:$G$145,Media_Cliente_Mes!$A$2:$A$145,$K$3,Media_Cliente_Mes!$B$2:$B$145,$A3),0) -> 0 | L8: =IFERROR(SUMIFS(Media_Cliente_Mes!$G$2:$G$145,Media_Cliente_Mes!$A$2:$A$145,$L$3,Media_Cliente_Mes!$B$2:$B$145,$A3),0) -> 0 | M8: =IFERROR(SUMIFS(Media_Cliente_Mes!$G$2:$G$145,Media_Cliente_Mes!$A$2:$A$145,$M$3,Media_Cliente_Mes!$B$2:$B$145,$A3),0) -> 0 | N8: =IFERROR(SUMPRODUCT(B4:M4,B8:M8)/SUM(B4:M4),0) -> 1.5692925
A9: Vol. Rodo (t) | B9: =IFERROR(SUMIFS(Media_Cliente_Mes!$H$2:$H$145,Media_Cliente_Mes!$A$2:$A$145,$B$3,Media_Cliente_Mes!$B$2:$B$145,$A3),0) -> 0 | C9: =IFERROR(SUMIFS(Media_Cliente_Mes!$H$2:$H$145,Media_Cliente_Mes!$A$2:$A$145,$C$3,Media_Cliente_Mes!$B$2:$B$145,$A3),0) -> 39842.6 | D9: =IFERROR(SUMIFS(Media_Cliente_Mes!$H$2:$H$145,Media_Cliente_Mes!$A$2:$A$145,$D$3,Media_Cliente_Mes!$B$2:$B$145,$A3),0) -> 664.72 | E9: =IFERROR(SUMIFS(Media_Cliente_Mes!$H$2:$H$145,Media_Cliente_Mes!$A$2:$A$145,$E$3,Media_Cliente_Mes!$B$2:$B$145,$A3),0) -> 25284.64 | F9: =IFERROR(SUMIFS(Media_Cliente_Mes!$H$2:$H$145,Media_Cliente_Mes!$A$2:$A$145,$F$3,Media_Cliente_Mes!$B$2:$B$145,$A3),0) -> 10502.32 | G9: =IFERROR(SUMIFS(Media_Cliente_Mes!$H$2:$H$145,Media_Cliente_Mes!$A$2:$A$145,$G$3,Media_Cliente_Mes!$B$2:$B$145,$A3),0) -> 47.73 | H9: =IFERROR(SUMIFS(Media_Cliente_Mes!$H$2:$H$145,Media_Cliente_Mes!$A$2:$A$145,$H$3,Media_Cliente_Mes!$B$2:$B$145,$A3),0) -> 33837.06 | I9: =IFERROR(SUMIFS(Media_Cliente_Mes!$H$2:$H$145,Media_Cliente_Mes!$A$2:$A$145,$I$3,Media_Cliente_Mes!$B$2:$B$145,$A3),0) -> 0 | J9: =IFERROR(SUMIFS(Media_Cliente_Mes!$H$2:$H$145,Media_Cliente_Mes!$A$2:$A$145,$J$3,Media_Cliente_Mes!$B$2:$B$145,$A3),0) -> 0 | K9: =IFERROR(SUMIFS(Media_Cliente_Mes!$H$2:$H$145,Media_Cliente_Mes!$A$2:$A$145,$K$3,Media_Cliente_Mes!$B$2:$B$145,$A3),0) -> 0 | L9: =IFERROR(SUMIFS(Media_Cliente_Mes!$H$2:$H$145,Media_Cliente_Mes!$A$2:$A$145,$L$3,Media_Cliente_Mes!$B$2:$B$145,$A3),0) -> 0 | M9: =IFERROR(SUMIFS(Media_Cliente_Mes!$H$2:$H$145,Media_Cliente_Mes!$A$2:$A$145,$M$3,Media_Cliente_Mes!$B$2:$B$145,$A3),0) -> 0 | N9: =SUM(B9:M9) -> 110179.07
A10: Vol. Ferro (t) | B10: =IFERROR(SUMIFS(Media_Cliente_Mes!$I$2:$I$145,Media_Cliente_Mes!$A$2:$A$145,$B$3,Media_Cliente_Mes!$B$2:$B$145,$A3),0) -> 0 | C10: =IFERROR(SUMIFS(Media_Cliente_Mes!$I$2:$I$145,Media_Cliente_Mes!$A$2:$A$145,$C$3,Media_Cliente_Mes!$B$2:$B$145,$A3),0) -> 0 | D10: =IFERROR(SUMIFS(Media_Cliente_Mes!$I$2:$I$145,Media_Cliente_Mes!$A$2:$A$145,$D$3,Media_Cliente_Mes!$B$2:$B$145,$A3),0) -> 18227.02 | E10: =IFERROR(SUMIFS(Media_Cliente_Mes!$I$2:$I$145,Media_Cliente_Mes!$A$2:$A$145,$E$3,Media_Cliente_Mes!$B$2:$B$145,$A3),0) -> 1049.69 | F10: =IFERROR(SUMIFS(Media_Cliente_Mes!$I$2:$I$145,Media_Cliente_Mes!$A$2:$A$145,$F$3,Media_Cliente_Mes!$B$2:$B$145,$A3),0) -> 47630.96 | G10: =IFERROR(SUMIFS(Media_Cliente_Mes!$I$2:$I$145,Media_Cliente_Mes!$A$2:$A$145,$G$3,Media_Cliente_Mes!$B$2:$B$145,$A3),0) -> 48512.9 | H10: =IFERROR(SUMIFS(Media_Cliente_Mes!$I$2:$I$145,Media_Cliente_Mes!$A$2:$A$145,$H$3,Media_Cliente_Mes!$B$2:$B$145,$A3),0) -> 38216.63 | I10: =IFERROR(SUMIFS(Media_Cliente_Mes!$I$2:$I$145,Media_Cliente_Mes!$A$2:$A$145,$I$3,Media_Cliente_Mes!$B$2:$B$145,$A3),0) -> 0 | J10: =IFERROR(SUMIFS(Media_Cliente_Mes!$I$2:$I$145,Media_Cliente_Mes!$A$2:$A$145,$J$3,Media_Cliente_Mes!$B$2:$B$145,$A3),0) -> 0 | K10: =IFERROR(SUMIFS(Media_Cliente_Mes!$I$2:$I$145,Media_Cliente_Mes!$A$2:$A$145,$K$3,Media_Cliente_Mes!$B$2:$B$145,$A3),0) -> 0 | L10: =IFERROR(SUMIFS(Media_Cliente_Mes!$I$2:$I$145,Media_Cliente_Mes!$A$2:$A$145,$L$3,Media_Cliente_Mes!$B$2:$B$145,$A3),0) -> 0 | M10: =IFERROR(SUMIFS(Media_Cliente_Mes!$I$2:$I$145,Media_Cliente_Mes!$A$2:$A$145,$M$3,Media_Cliente_Mes!$B$2:$B$145,$A3),0) -> 0 | N10: =SUM(B10:M10) -> 153637.2
A12: Fev | B12: Amaggi | C12: Brejeiro | D12: Caramuru | E12: Cargill | F12: Cofco | G12: 3Tentos | H12: Bunge | I12: ADM | J12: Aliança | K12: Olfar | L12: Novo06 | M12: Novo07 | N12: Media Pool
A13: Volume | B13: =IFERROR(SUMIFS(Media_Cliente_Mes!$C$2:$C$145,Media_Cliente_Mes!$A$2:$A$145,$B$12,Media_Cliente_Mes!$B$2:$B$145,$A12),0) -> 0 | C13: =IFERROR(SUMIFS(Media_Cliente_Mes!$C$2:$C$145,Media_Cliente_Mes!$A$2:$A$145,$C$12,Media_Cliente_Mes!$B$2:$B$145,$A12),0) -> 30370.33 | D13: =IFERROR(SUMIFS(Media_Cliente_Mes!$C$2:$C$145,Media_Cliente_Mes!$A$2:$A$145,$D$12,Media_Cliente_Mes!$B$2:$B$145,$A12),0) -> 9485.48 | E13: =IFERROR(SUMIFS(Media_Cliente_Mes!$C$2:$C$145,Media_Cliente_Mes!$A$2:$A$145,$E$12,Media_Cliente_Mes!$B$2:$B$145,$A12),0) -> 62578.1 | F13: =IFERROR(SUMIFS(Media_Cliente_Mes!$C$2:$C$145,Media_Cliente_Mes!$A$2:$A$145,$F$12,Media_Cliente_Mes!$B$2:$B$145,$A12),0) -> 53224.28 | G13: =IFERROR(SUMIFS(Media_Cliente_Mes!$C$2:$C$145,Media_Cliente_Mes!$A$2:$A$145,$G$12,Media_Cliente_Mes!$B$2:$B$145,$A12),0) -> 41884.18 | H13: =IFERROR(SUMIFS(Media_Cliente_Mes!$C$2:$C$145,Media_Cliente_Mes!$A$2:$A$145,$H$12,Media_Cliente_Mes!$B$2:$B$145,$A12),0) -> 101673.63 | I13: =IFERROR(SUMIFS(Media_Cliente_Mes!$C$2:$C$145,Media_Cliente_Mes!$A$2:$A$145,$I$12,Media_Cliente_Mes!$B$2:$B$145,$A12),0) -> 0 | J13: =IFERROR(SUMIFS(Media_Cliente_Mes!$C$2:$C$145,Media_Cliente_Mes!$A$2:$A$145,$J$12,Media_Cliente_Mes!$B$2:$B$145,$A12),0) -> 0 | K13: =IFERROR(SUMIFS(Media_Cliente_Mes!$C$2:$C$145,Media_Cliente_Mes!$A$2:$A$145,$K$12,Media_Cliente_Mes!$B$2:$B$145,$A12),0) -> 0 | L13: =IFERROR(SUMIFS(Media_Cliente_Mes!$C$2:$C$145,Media_Cliente_Mes!$A$2:$A$145,$L$12,Media_Cliente_Mes!$B$2:$B$145,$A12),0) -> 0 | M13: =IFERROR(SUMIFS(Media_Cliente_Mes!$C$2:$C$145,Media_Cliente_Mes!$A$2:$A$145,$M$12,Media_Cliente_Mes!$B$2:$B$145,$A12),0) -> 0 | N13: =SUM(B13:M13) -> 299216
A14: Proteina Bruta (%) | B14: =IFERROR(SUMIFS(Media_Cliente_Mes!$D$2:$D$145,Media_Cliente_Mes!$A$2:$A$145,$B$12,Media_Cliente_Mes!$B$2:$B$145,$A12),0) -> 0 | C14: =IFERROR(SUMIFS(Media_Cliente_Mes!$D$2:$D$145,Media_Cliente_Mes!$A$2:$A$145,$C$12,Media_Cliente_Mes!$B$2:$B$145,$A12),0) -> 47.98074 | D14: =IFERROR(SUMIFS(Media_Cliente_Mes!$D$2:$D$145,Media_Cliente_Mes!$A$2:$A$145,$D$12,Media_Cliente_Mes!$B$2:$B$145,$A12),0) -> 47.208667 | E14: =IFERROR(SUMIFS(Media_Cliente_Mes!$D$2:$D$145,Media_Cliente_Mes!$A$2:$A$145,$E$12,Media_Cliente_Mes!$B$2:$B$145,$A12),0) -> 46.969315 | F14: =IFERROR(SUMIFS(Media_Cliente_Mes!$D$2:$D$145,Media_Cliente_Mes!$A$2:$A$145,$F$12,Media_Cliente_Mes!$B$2:$B$145,$A12),0) -> 47.741003 | G14: =IFERROR(SUMIFS(Media_Cliente_Mes!$D$2:$D$145,Media_Cliente_Mes!$A$2:$A$145,$G$12,Media_Cliente_Mes!$B$2:$B$145,$A12),0) -> 47.148488 | H14: =IFERROR(SUMIFS(Media_Cliente_Mes!$D$2:$D$145,Media_Cliente_Mes!$A$2:$A$145,$H$12,Media_Cliente_Mes!$B$2:$B$145,$A12),0) -> 47.259671 | I14: =IFERROR(SUMIFS(Media_Cliente_Mes!$D$2:$D$145,Media_Cliente_Mes!$A$2:$A$145,$I$12,Media_Cliente_Mes!$B$2:$B$145,$A12),0) -> 0 | J14: =IFERROR(SUMIFS(Media_Cliente_Mes!$D$2:$D$145,Media_Cliente_Mes!$A$2:$A$145,$J$12,Media_Cliente_Mes!$B$2:$B$145,$A12),0) -> 0 | K14: =IFERROR(SUMIFS(Media_Cliente_Mes!$D$2:$D$145,Media_Cliente_Mes!$A$2:$A$145,$K$12,Media_Cliente_Mes!$B$2:$B$145,$A12),0) -> 0 | L14: =IFERROR(SUMIFS(Media_Cliente_Mes!$D$2:$D$145,Media_Cliente_Mes!$A$2:$A$145,$L$12,Media_Cliente_Mes!$B$2:$B$145,$A12),0) -> 0 | M14: =IFERROR(SUMIFS(Media_Cliente_Mes!$D$2:$D$145,Media_Cliente_Mes!$A$2:$A$145,$M$12,Media_Cliente_Mes!$B$2:$B$145,$A12),0) -> 0 | N14: =IFERROR(SUMPRODUCT(B13:M13,B14:M14)/SUM(B13:M13),0) -> 47.340573
A15: Umidade (%) | B15: =IFERROR(SUMIFS(Media_Cliente_Mes!$E$2:$E$145,Media_Cliente_Mes!$A$2:$A$145,$B$12,Media_Cliente_Mes!$B$2:$B$145,$A12),0) -> 0 | C15: =IFERROR(SUMIFS(Media_Cliente_Mes!$E$2:$E$145,Media_Cliente_Mes!$A$2:$A$145,$C$12,Media_Cliente_Mes!$B$2:$B$145,$A12),0) -> 11.558493 | D15: =IFERROR(SUMIFS(Media_Cliente_Mes!$E$2:$E$145,Media_Cliente_Mes!$A$2:$A$145,$D$12,Media_Cliente_Mes!$B$2:$B$145,$A12),0) -> 12.719272 | E15: =IFERROR(SUMIFS(Media_Cliente_Mes!$E$2:$E$145,Media_Cliente_Mes!$A$2:$A$145,$E$12,Media_Cliente_Mes!$B$2:$B$145,$A12),0) -> 12.33938 | F15: =IFERROR(SUMIFS(Media_Cliente_Mes!$E$2:$E$145,Media_Cliente_Mes!$A$2:$A$145,$F$12,Media_Cliente_Mes!$B$2:$B$145,$A12),0) -> 12.236462 | G15: =IFERROR(SUMIFS(Media_Cliente_Mes!$E$2:$E$145,Media_Cliente_Mes!$A$2:$A$145,$G$12,Media_Cliente_Mes!$B$2:$B$145,$A12),0) -> 12.236235 | H15: =IFERROR(SUMIFS(Media_Cliente_Mes!$E$2:$E$145,Media_Cliente_Mes!$A$2:$A$145,$H$12,Media_Cliente_Mes!$B$2:$B$145,$A12),0) -> 12.357228 | I15: =IFERROR(SUMIFS(Media_Cliente_Mes!$E$2:$E$145,Media_Cliente_Mes!$A$2:$A$145,$I$12,Media_Cliente_Mes!$B$2:$B$145,$A12),0) -> 0 | J15: =IFERROR(SUMIFS(Media_Cliente_Mes!$E$2:$E$145,Media_Cliente_Mes!$A$2:$A$145,$J$12,Media_Cliente_Mes!$B$2:$B$145,$A12),0) -> 0 | K15: =IFERROR(SUMIFS(Media_Cliente_Mes!$E$2:$E$145,Media_Cliente_Mes!$A$2:$A$145,$K$12,Media_Cliente_Mes!$B$2:$B$145,$A12),0) -> 0 | L15: =IFERROR(SUMIFS(Media_Cliente_Mes!$E$2:$E$145,Media_Cliente_Mes!$A$2:$A$145,$L$12,Media_Cliente_Mes!$B$2:$B$145,$A12),0) -> 0 | M15: =IFERROR(SUMIFS(Media_Cliente_Mes!$E$2:$E$145,Media_Cliente_Mes!$A$2:$A$145,$M$12,Media_Cliente_Mes!$B$2:$B$145,$A12),0) -> 0 | N15: =IFERROR(SUMPRODUCT(B13:M13,B15:M15)/SUM(B13:M13),0) -> 12.245483
A16: Fibra (%) | B16: =IFERROR(SUMIFS(Media_Cliente_Mes!$F$2:$F$145,Media_Cliente_Mes!$A$2:$A$145,$B$12,Media_Cliente_Mes!$B$2:$B$145,$A12),0) -> 0 | C16: =IFERROR(SUMIFS(Media_Cliente_Mes!$F$2:$F$145,Media_Cliente_Mes!$A$2:$A$145,$C$12,Media_Cliente_Mes!$B$2:$B$145,$A12),0) -> 3.4609544 | D16: =IFERROR(SUMIFS(Media_Cliente_Mes!$F$2:$F$145,Media_Cliente_Mes!$A$2:$A$145,$D$12,Media_Cliente_Mes!$B$2:$B$145,$A12),0) -> 3.7313673 | E16: =IFERROR(SUMIFS(Media_Cliente_Mes!$F$2:$F$145,Media_Cliente_Mes!$A$2:$A$145,$E$12,Media_Cliente_Mes!$B$2:$B$145,$A12),0) -> 3.7083902 | F16: =IFERROR(SUMIFS(Media_Cliente_Mes!$F$2:$F$145,Media_Cliente_Mes!$A$2:$A$145,$F$12,Media_Cliente_Mes!$B$2:$B$145,$A12),0) -> 3.4970776 | G16: =IFERROR(SUMIFS(Media_Cliente_Mes!$F$2:$F$145,Media_Cliente_Mes!$A$2:$A$145,$G$12,Media_Cliente_Mes!$B$2:$B$145,$A12),0) -> 3.7498197 | H16: =IFERROR(SUMIFS(Media_Cliente_Mes!$F$2:$F$145,Media_Cliente_Mes!$A$2:$A$145,$H$12,Media_Cliente_Mes!$B$2:$B$145,$A12),0) -> 3.6090273 | I16: =IFERROR(SUMIFS(Media_Cliente_Mes!$F$2:$F$145,Media_Cliente_Mes!$A$2:$A$145,$I$12,Media_Cliente_Mes!$B$2:$B$145,$A12),0) -> 0 | J16: =IFERROR(SUMIFS(Media_Cliente_Mes!$F$2:$F$145,Media_Cliente_Mes!$A$2:$A$145,$J$12,Media_Cliente_Mes!$B$2:$B$145,$A12),0) -> 0 | K16: =IFERROR(SUMIFS(Media_Cliente_Mes!$F$2:$F$145,Media_Cliente_Mes!$A$2:$A$145,$K$12,Media_Cliente_Mes!$B$2:$B$145,$A12),0) -> 0 | L16: =IFERROR(SUMIFS(Media_Cliente_Mes!$F$2:$F$145,Media_Cliente_Mes!$A$2:$A$145,$L$12,Media_Cliente_Mes!$B$2:$B$145,$A12),0) -> 0 | M16: =IFERROR(SUMIFS(Media_Cliente_Mes!$F$2:$F$145,Media_Cliente_Mes!$A$2:$A$145,$M$12,Media_Cliente_Mes!$B$2:$B$145,$A12),0) -> 0 | N16: =IFERROR(SUMPRODUCT(B13:M13,B16:M16)/SUM(B13:M13),0) -> 3.6184516
A17: Oleo (%) | B17: =IFERROR(SUMIFS(Media_Cliente_Mes!$G$2:$G$145,Media_Cliente_Mes!$A$2:$A$145,$B$12,Media_Cliente_Mes!$B$2:$B$145,$A12),0) -> 0 | C17: =IFERROR(SUMIFS(Media_Cliente_Mes!$G$2:$G$145,Media_Cliente_Mes!$A$2:$A$145,$C$12,Media_Cliente_Mes!$B$2:$B$145,$A12),0) -> 1.3115992 | D17: =IFERROR(SUMIFS(Media_Cliente_Mes!$G$2:$G$145,Media_Cliente_Mes!$A$2:$A$145,$D$12,Media_Cliente_Mes!$B$2:$B$145,$A12),0) -> 1.1685137 | E17: =IFERROR(SUMIFS(Media_Cliente_Mes!$G$2:$G$145,Media_Cliente_Mes!$A$2:$A$145,$E$12,Media_Cliente_Mes!$B$2:$B$145,$A12),0) -> 1.7318407 | F17: =IFERROR(SUMIFS(Media_Cliente_Mes!$G$2:$G$145,Media_Cliente_Mes!$A$2:$A$145,$F$12,Media_Cliente_Mes!$B$2:$B$145,$A12),0) -> 1.7741349 | G17: =IFERROR(SUMIFS(Media_Cliente_Mes!$G$2:$G$145,Media_Cliente_Mes!$A$2:$A$145,$G$12,Media_Cliente_Mes!$B$2:$B$145,$A12),0) -> 1.5862946 | H17: =IFERROR(SUMIFS(Media_Cliente_Mes!$G$2:$G$145,Media_Cliente_Mes!$A$2:$A$145,$H$12,Media_Cliente_Mes!$B$2:$B$145,$A12),0) -> 1.6916691 | I17: =IFERROR(SUMIFS(Media_Cliente_Mes!$G$2:$G$145,Media_Cliente_Mes!$A$2:$A$145,$I$12,Media_Cliente_Mes!$B$2:$B$145,$A12),0) -> 0 | J17: =IFERROR(SUMIFS(Media_Cliente_Mes!$G$2:$G$145,Media_Cliente_Mes!$A$2:$A$145,$J$12,Media_Cliente_Mes!$B$2:$B$145,$A12),0) -> 0 | K17: =IFERROR(SUMIFS(Media_Cliente_Mes!$G$2:$G$145,Media_Cliente_Mes!$A$2:$A$145,$K$12,Media_Cliente_Mes!$B$2:$B$145,$A12),0) -> 0 | L17: =IFERROR(SUMIFS(Media_Cliente_Mes!$G$2:$G$145,Media_Cliente_Mes!$A$2:$A$145,$L$12,Media_Cliente_Mes!$B$2:$B$145,$A12),0) -> 0 | M17: =IFERROR(SUMIFS(Media_Cliente_Mes!$G$2:$G$145,Media_Cliente_Mes!$A$2:$A$145,$M$12,Media_Cliente_Mes!$B$2:$B$145,$A12),0) -> 0 | N17: =IFERROR(SUMPRODUCT(B13:M13,B17:M17)/SUM(B13:M13),0) -> 1.6448277
A18: Vol. Rodo (t) | B18: =IFERROR(SUMIFS(Media_Cliente_Mes!$H$2:$H$145,Media_Cliente_Mes!$A$2:$A$145,$B$12,Media_Cliente_Mes!$B$2:$B$145,$A12),0) -> 0 | C18: =IFERROR(SUMIFS(Media_Cliente_Mes!$H$2:$H$145,Media_Cliente_Mes!$A$2:$A$145,$C$12,Media_Cliente_Mes!$B$2:$B$145,$A12),0) -> 30370.33 | D18: =IFERROR(SUMIFS(Media_Cliente_Mes!$H$2:$H$145,Media_Cliente_Mes!$A$2:$A$145,$D$12,Media_Cliente_Mes!$B$2:$B$145,$A12),0) -> 0 | E18: =IFERROR(SUMIFS(Media_Cliente_Mes!$H$2:$H$145,Media_Cliente_Mes!$A$2:$A$145,$E$12,Media_Cliente_Mes!$B$2:$B$145,$A12),0) -> 11853.83 | F18: =IFERROR(SUMIFS(Media_Cliente_Mes!$H$2:$H$145,Media_Cliente_Mes!$A$2:$A$145,$F$12,Media_Cliente_Mes!$B$2:$B$145,$A12),0) -> 0 | G18: =IFERROR(SUMIFS(Media_Cliente_Mes!$H$2:$H$145,Media_Cliente_Mes!$A$2:$A$145,$G$12,Media_Cliente_Mes!$B$2:$B$145,$A12),0) -> 39.21 | H18: =IFERROR(SUMIFS(Media_Cliente_Mes!$H$2:$H$145,Media_Cliente_Mes!$A$2:$A$145,$H$12,Media_Cliente_Mes!$B$2:$B$145,$A12),0) -> 0 | I18: =IFERROR(SUMIFS(Media_Cliente_Mes!$H$2:$H$145,Media_Cliente_Mes!$A$2:$A$145,$I$12,Media_Cliente_Mes!$B$2:$B$145,$A12),0) -> 0 | J18: =IFERROR(SUMIFS(Media_Cliente_Mes!$H$2:$H$145,Media_Cliente_Mes!$A$2:$A$145,$J$12,Media_Cliente_Mes!$B$2:$B$145,$A12),0) -> 0 | K18: =IFERROR(SUMIFS(Media_Cliente_Mes!$H$2:$H$145,Media_Cliente_Mes!$A$2:$A$145,$K$12,Media_Cliente_Mes!$B$2:$B$145,$A12),0) -> 0 | L18: =IFERROR(SUMIFS(Media_Cliente_Mes!$H$2:$H$145,Media_Cliente_Mes!$A$2:$A$145,$L$12,Media_Cliente_Mes!$B$2:$B$145,$A12),0) -> 0 | M18: =IFERROR(SUMIFS(Media_Cliente_Mes!$H$2:$H$145,Media_Cliente_Mes!$A$2:$A$145,$M$12,Media_Cliente_Mes!$B$2:$B$145,$A12),0) -> 0 | N18: =SUM(B18:M18) -> 42263.37
A19: Vol. Ferro (t) | B19: =IFERROR(SUMIFS(Media_Cliente_Mes!$I$2:$I$145,Media_Cliente_Mes!$A$2:$A$145,$B$12,Media_Cliente_Mes!$B$2:$B$145,$A12),0) -> 0 | C19: =IFERROR(SUMIFS(Media_Cliente_Mes!$I$2:$I$145,Media_Cliente_Mes!$A$2:$A$145,$C$12,Media_Cliente_Mes!$B$2:$B$145,$A12),0) -> 0 | D19: =IFERROR(SUMIFS(Media_Cliente_Mes!$I$2:$I$145,Media_Cliente_Mes!$A$2:$A$145,$D$12,Media_Cliente_Mes!$B$2:$B$145,$A12),0) -> 9485.48 | E19: =IFERROR(SUMIFS(Media_Cliente_Mes!$I$2:$I$145,Media_Cliente_Mes!$A$2:$A$145,$E$12,Media_Cliente_Mes!$B$2:$B$145,$A12),0) -> 50724.27 | F19: =IFERROR(SUMIFS(Media_Cliente_Mes!$I$2:$I$145,Media_Cliente_Mes!$A$2:$A$145,$F$12,Media_Cliente_Mes!$B$2:$B$145,$A12),0) -> 53224.28 | G19: =IFERROR(SUMIFS(Media_Cliente_Mes!$I$2:$I$145,Media_Cliente_Mes!$A$2:$A$145,$G$12,Media_Cliente_Mes!$B$2:$B$145,$A12),0) -> 41844.97 | H19: =IFERROR(SUMIFS(Media_Cliente_Mes!$I$2:$I$145,Media_Cliente_Mes!$A$2:$A$145,$H$12,Media_Cliente_Mes!$B$2:$B$145,$A12),0) -> 101673.63 | I19: =IFERROR(SUMIFS(Media_Cliente_Mes!$I$2:$I$145,Media_Cliente_Mes!$A$2:$A$145,$I$12,Media_Cliente_Mes!$B$2:$B$145,$A12),0) -> 0 | J19: =IFERROR(SUMIFS(Media_Cliente_Mes!$I$2:$I$145,Media_Cliente_Mes!$A$2:$A$145,$J$12,Media_Cliente_Mes!$B$2:$B$145,$A12),0) -> 0 | K19: =IFERROR(SUMIFS(Media_Cliente_Mes!$I$2:$I$145,Media_Cliente_Mes!$A$2:$A$145,$K$12,Media_Cliente_Mes!$B$2:$B$145,$A12),0) -> 0 | L19: =IFERROR(SUMIFS(Media_Cliente_Mes!$I$2:$I$145,Media_Cliente_Mes!$A$2:$A$145,$L$12,Media_Cliente_Mes!$B$2:$B$145,$A12),0) -> 0 | M19: =IFERROR(SUMIFS(Media_Cliente_Mes!$I$2:$I$145,Media_Cliente_Mes!$A$2:$A$145,$M$12,Media_Cliente_Mes!$B$2:$B$145,$A12),0) -> 0 | N19: =SUM(B19:M19) -> 256952.63
A21: Mar | B21: Amaggi | C21: Brejeiro | D21: Caramuru | E21: Cargill | F21: Cofco | G21: 3Tentos | H21: Bunge | I21: ADM | J21: Aliança | K21: Olfar | L21: Novo06 | M21: Novo07 | N21: Media Pool
A22: Volume | B22: =IFERROR(SUMIFS(Media_Cliente_Mes!$C$2:$C$145,Media_Cliente_Mes!$A$2:$A$145,$B$21,Media_Cliente_Mes!$B$2:$B$145,$A21),0) -> 0 | C22: =IFERROR(SUMIFS(Media_Cliente_Mes!$C$2:$C$145,Media_Cliente_Mes!$A$2:$A$145,$C$21,Media_Cliente_Mes!$B$2:$B$145,$A21),0) -> 43330.53 | D22: =IFERROR(SUMIFS(Media_Cliente_Mes!$C$2:$C$145,Media_Cliente_Mes!$A$2:$A$145,$D$21,Media_Cliente_Mes!$B$2:$B$145,$A21),0) -> 12278.31 | E22: =IFERROR(SUMIFS(Media_Cliente_Mes!$C$2:$C$145,Media_Cliente_Mes!$A$2:$A$145,$E$21,Media_Cliente_Mes!$B$2:$B$145,$A21),0) -> 60137.37 | F22: =IFERROR(SUMIFS(Media_Cliente_Mes!$C$2:$C$145,Media_Cliente_Mes!$A$2:$A$145,$F$21,Media_Cliente_Mes!$B$2:$B$145,$A21),0) -> 66365.71 | G22: =IFERROR(SUMIFS(Media_Cliente_Mes!$C$2:$C$145,Media_Cliente_Mes!$A$2:$A$145,$G$21,Media_Cliente_Mes!$B$2:$B$145,$A21),0) -> 58475.74 | H22: =IFERROR(SUMIFS(Media_Cliente_Mes!$C$2:$C$145,Media_Cliente_Mes!$A$2:$A$145,$H$21,Media_Cliente_Mes!$B$2:$B$145,$A21),0) -> 141.56 | I22: =IFERROR(SUMIFS(Media_Cliente_Mes!$C$2:$C$145,Media_Cliente_Mes!$A$2:$A$145,$I$21,Media_Cliente_Mes!$B$2:$B$145,$A21),0) -> 0 | J22: =IFERROR(SUMIFS(Media_Cliente_Mes!$C$2:$C$145,Media_Cliente_Mes!$A$2:$A$145,$J$21,Media_Cliente_Mes!$B$2:$B$145,$A21),0) -> 0 | K22: =IFERROR(SUMIFS(Media_Cliente_Mes!$C$2:$C$145,Media_Cliente_Mes!$A$2:$A$145,$K$21,Media_Cliente_Mes!$B$2:$B$145,$A21),0) -> 0 | L22: =IFERROR(SUMIFS(Media_Cliente_Mes!$C$2:$C$145,Media_Cliente_Mes!$A$2:$A$145,$L$21,Media_Cliente_Mes!$B$2:$B$145,$A21),0) -> 0 | M22: =IFERROR(SUMIFS(Media_Cliente_Mes!$C$2:$C$145,Media_Cliente_Mes!$A$2:$A$145,$M$21,Media_Cliente_Mes!$B$2:$B$145,$A21),0) -> 0 | N22: =SUM(B22:M22) -> 240729.22
A23: Proteina Bruta (%) | B23: =IFERROR(SUMIFS(Media_Cliente_Mes!$D$2:$D$145,Media_Cliente_Mes!$A$2:$A$145,$B$21,Media_Cliente_Mes!$B$2:$B$145,$A21),0) -> 0 | C23: =IFERROR(SUMIFS(Media_Cliente_Mes!$D$2:$D$145,Media_Cliente_Mes!$A$2:$A$145,$C$21,Media_Cliente_Mes!$B$2:$B$145,$A21),0) -> 47.572986 | D23: =IFERROR(SUMIFS(Media_Cliente_Mes!$D$2:$D$145,Media_Cliente_Mes!$A$2:$A$145,$D$21,Media_Cliente_Mes!$B$2:$B$145,$A21),0) -> 48.003435 | E23: =IFERROR(SUMIFS(Media_Cliente_Mes!$D$2:$D$145,Media_Cliente_Mes!$A$2:$A$145,$E$21,Media_Cliente_Mes!$B$2:$B$145,$A21),0) -> 47.227053 | F23: =IFERROR(SUMIFS(Media_Cliente_Mes!$D$2:$D$145,Media_Cliente_Mes!$A$2:$A$145,$F$21,Media_Cliente_Mes!$B$2:$B$145,$A21),0) -> 47.310662 | G23: =IFERROR(SUMIFS(Media_Cliente_Mes!$D$2:$D$145,Media_Cliente_Mes!$A$2:$A$145,$G$21,Media_Cliente_Mes!$B$2:$B$145,$A21),0) -> 47.144729 | H23: =IFERROR(SUMIFS(Media_Cliente_Mes!$D$2:$D$145,Media_Cliente_Mes!$A$2:$A$145,$H$21,Media_Cliente_Mes!$B$2:$B$145,$A21),0) -> 47.67 | I23: =IFERROR(SUMIFS(Media_Cliente_Mes!$D$2:$D$145,Media_Cliente_Mes!$A$2:$A$145,$I$21,Media_Cliente_Mes!$B$2:$B$145,$A21),0) -> 0 | J23: =IFERROR(SUMIFS(Media_Cliente_Mes!$D$2:$D$145,Media_Cliente_Mes!$A$2:$A$145,$J$21,Media_Cliente_Mes!$B$2:$B$145,$A21),0) -> 0 | K23: =IFERROR(SUMIFS(Media_Cliente_Mes!$D$2:$D$145,Media_Cliente_Mes!$A$2:$A$145,$K$21,Media_Cliente_Mes!$B$2:$B$145,$A21),0) -> 0 | L23: =IFERROR(SUMIFS(Media_Cliente_Mes!$D$2:$D$145,Media_Cliente_Mes!$A$2:$A$145,$L$21,Media_Cliente_Mes!$B$2:$B$145,$A21),0) -> 0 | M23: =IFERROR(SUMIFS(Media_Cliente_Mes!$D$2:$D$145,Media_Cliente_Mes!$A$2:$A$145,$M$21,Media_Cliente_Mes!$B$2:$B$145,$A21),0) -> 0 | N23: =IFERROR(SUMPRODUCT(B22:M22,B23:M23)/SUM(B22:M22),0) -> 47.332232
A24: Umidade (%) | B24: =IFERROR(SUMIFS(Media_Cliente_Mes!$E$2:$E$145,Media_Cliente_Mes!$A$2:$A$145,$B$21,Media_Cliente_Mes!$B$2:$B$145,$A21),0) -> 0 | C24: =IFERROR(SUMIFS(Media_Cliente_Mes!$E$2:$E$145,Media_Cliente_Mes!$A$2:$A$145,$C$21,Media_Cliente_Mes!$B$2:$B$145,$A21),0) -> 11.602546 | D24: =IFERROR(SUMIFS(Media_Cliente_Mes!$E$2:$E$145,Media_Cliente_Mes!$A$2:$A$145,$D$21,Media_Cliente_Mes!$B$2:$B$145,$A21),0) -> 12.397771 | E24: =IFERROR(SUMIFS(Media_Cliente_Mes!$E$2:$E$145,Media_Cliente_Mes!$A$2:$A$145,$E$21,Media_Cliente_Mes!$B$2:$B$145,$A21),0) -> 12.141234 | F24: =IFERROR(SUMIFS(Media_Cliente_Mes!$E$2:$E$145,Media_Cliente_Mes!$A$2:$A$145,$F$21,Media_Cliente_Mes!$B$2:$B$145,$A21),0) -> 12.365805 | G24: =IFERROR(SUMIFS(Media_Cliente_Mes!$E$2:$E$145,Media_Cliente_Mes!$A$2:$A$145,$G$21,Media_Cliente_Mes!$B$2:$B$145,$A21),0) -> 12.36645 | H24: =IFERROR(SUMIFS(Media_Cliente_Mes!$E$2:$E$145,Media_Cliente_Mes!$A$2:$A$145,$H$21,Media_Cliente_Mes!$B$2:$B$145,$A21),0) -> 12.33 | I24: =IFERROR(SUMIFS(Media_Cliente_Mes!$E$2:$E$145,Media_Cliente_Mes!$A$2:$A$145,$I$21,Media_Cliente_Mes!$B$2:$B$145,$A21),0) -> 0 | J24: =IFERROR(SUMIFS(Media_Cliente_Mes!$E$2:$E$145,Media_Cliente_Mes!$A$2:$A$145,$J$21,Media_Cliente_Mes!$B$2:$B$145,$A21),0) -> 0 | K24: =IFERROR(SUMIFS(Media_Cliente_Mes!$E$2:$E$145,Media_Cliente_Mes!$A$2:$A$145,$K$21,Media_Cliente_Mes!$B$2:$B$145,$A21),0) -> 0 | L24: =IFERROR(SUMIFS(Media_Cliente_Mes!$E$2:$E$145,Media_Cliente_Mes!$A$2:$A$145,$L$21,Media_Cliente_Mes!$B$2:$B$145,$A21),0) -> 0 | M24: =IFERROR(SUMIFS(Media_Cliente_Mes!$E$2:$E$145,Media_Cliente_Mes!$A$2:$A$145,$M$21,Media_Cliente_Mes!$B$2:$B$145,$A21),0) -> 0 | N24: =IFERROR(SUMPRODUCT(B22:M22,B24:M24)/SUM(B22:M22),0) -> 12.174086
A25: Fibra (%) | B25: =IFERROR(SUMIFS(Media_Cliente_Mes!$F$2:$F$145,Media_Cliente_Mes!$A$2:$A$145,$B$21,Media_Cliente_Mes!$B$2:$B$145,$A21),0) -> 0 | C25: =IFERROR(SUMIFS(Media_Cliente_Mes!$F$2:$F$145,Media_Cliente_Mes!$A$2:$A$145,$C$21,Media_Cliente_Mes!$B$2:$B$145,$A21),0) -> 3.6616401 | D25: =IFERROR(SUMIFS(Media_Cliente_Mes!$F$2:$F$145,Media_Cliente_Mes!$A$2:$A$145,$D$21,Media_Cliente_Mes!$B$2:$B$145,$A21),0) -> 3.5424956 | E25: =IFERROR(SUMIFS(Media_Cliente_Mes!$F$2:$F$145,Media_Cliente_Mes!$A$2:$A$145,$E$21,Media_Cliente_Mes!$B$2:$B$145,$A21),0) -> 3.7329685 | F25: =IFERROR(SUMIFS(Media_Cliente_Mes!$F$2:$F$145,Media_Cliente_Mes!$A$2:$A$145,$F$21,Media_Cliente_Mes!$B$2:$B$145,$A21),0) -> 3.7222102 | G25: =IFERROR(SUMIFS(Media_Cliente_Mes!$F$2:$F$145,Media_Cliente_Mes!$A$2:$A$145,$G$21,Media_Cliente_Mes!$B$2:$B$145,$A21),0) -> 3.7273584 | H25: =IFERROR(SUMIFS(Media_Cliente_Mes!$F$2:$F$145,Media_Cliente_Mes!$A$2:$A$145,$H$21,Media_Cliente_Mes!$B$2:$B$145,$A21),0) -> 3.52 | I25: =IFERROR(SUMIFS(Media_Cliente_Mes!$F$2:$F$145,Media_Cliente_Mes!$A$2:$A$145,$I$21,Media_Cliente_Mes!$B$2:$B$145,$A21),0) -> 0 | J25: =IFERROR(SUMIFS(Media_Cliente_Mes!$F$2:$F$145,Media_Cliente_Mes!$A$2:$A$145,$J$21,Media_Cliente_Mes!$B$2:$B$145,$A21),0) -> 0 | K25: =IFERROR(SUMIFS(Media_Cliente_Mes!$F$2:$F$145,Media_Cliente_Mes!$A$2:$A$145,$K$21,Media_Cliente_Mes!$B$2:$B$145,$A21),0) -> 0 | L25: =IFERROR(SUMIFS(Media_Cliente_Mes!$F$2:$F$145,Media_Cliente_Mes!$A$2:$A$145,$L$21,Media_Cliente_Mes!$B$2:$B$145,$A21),0) -> 0 | M25: =IFERROR(SUMIFS(Media_Cliente_Mes!$F$2:$F$145,Media_Cliente_Mes!$A$2:$A$145,$M$21,Media_Cliente_Mes!$B$2:$B$145,$A21),0) -> 0 | N25: =IFERROR(SUMPRODUCT(B22:M22,B25:M25)/SUM(B22:M22),0) -> 3.7059607
A26: Oleo (%) | B26: =IFERROR(SUMIFS(Media_Cliente_Mes!$G$2:$G$145,Media_Cliente_Mes!$A$2:$A$145,$B$21,Media_Cliente_Mes!$B$2:$B$145,$A21),0) -> 0 | C26: =IFERROR(SUMIFS(Media_Cliente_Mes!$G$2:$G$145,Media_Cliente_Mes!$A$2:$A$145,$C$21,Media_Cliente_Mes!$B$2:$B$145,$A21),0) -> 1.2533877 | D26: =IFERROR(SUMIFS(Media_Cliente_Mes!$G$2:$G$145,Media_Cliente_Mes!$A$2:$A$145,$D$21,Media_Cliente_Mes!$B$2:$B$145,$A21),0) -> 1.3863973 | E26: =IFERROR(SUMIFS(Media_Cliente_Mes!$G$2:$G$145,Media_Cliente_Mes!$A$2:$A$145,$E$21,Media_Cliente_Mes!$B$2:$B$145,$A21),0) -> 1.5296845 | F26: =IFERROR(SUMIFS(Media_Cliente_Mes!$G$2:$G$145,Media_Cliente_Mes!$A$2:$A$145,$F$21,Media_Cliente_Mes!$B$2:$B$145,$A21),0) -> 1.5412065 | G26: =IFERROR(SUMIFS(Media_Cliente_Mes!$G$2:$G$145,Media_Cliente_Mes!$A$2:$A$145,$G$21,Media_Cliente_Mes!$B$2:$B$145,$A21),0) -> 1.6072603 | H26: =IFERROR(SUMIFS(Media_Cliente_Mes!$G$2:$G$145,Media_Cliente_Mes!$A$2:$A$145,$H$21,Media_Cliente_Mes!$B$2:$B$145,$A21),0) -> 1.23 | I26: =IFERROR(SUMIFS(Media_Cliente_Mes!$G$2:$G$145,Media_Cliente_Mes!$A$2:$A$145,$I$21,Media_Cliente_Mes!$B$2:$B$145,$A21),0) -> 0 | J26: =IFERROR(SUMIFS(Media_Cliente_Mes!$G$2:$G$145,Media_Cliente_Mes!$A$2:$A$145,$J$21,Media_Cliente_Mes!$B$2:$B$145,$A21),0) -> 0 | K26: =IFERROR(SUMIFS(Media_Cliente_Mes!$G$2:$G$145,Media_Cliente_Mes!$A$2:$A$145,$K$21,Media_Cliente_Mes!$B$2:$B$145,$A21),0) -> 0 | L26: =IFERROR(SUMIFS(Media_Cliente_Mes!$G$2:$G$145,Media_Cliente_Mes!$A$2:$A$145,$L$21,Media_Cliente_Mes!$B$2:$B$145,$A21),0) -> 0 | M26: =IFERROR(SUMIFS(Media_Cliente_Mes!$G$2:$G$145,Media_Cliente_Mes!$A$2:$A$145,$M$21,Media_Cliente_Mes!$B$2:$B$145,$A21),0) -> 0 | N26: =IFERROR(SUMPRODUCT(B22:M22,B26:M26)/SUM(B22:M22),0) -> 1.4944878
A27: Vol. Rodo (t) | B27: =IFERROR(SUMIFS(Media_Cliente_Mes!$H$2:$H$145,Media_Cliente_Mes!$A$2:$A$145,$B$21,Media_Cliente_Mes!$B$2:$B$145,$A21),0) -> 0 | C27: =IFERROR(SUMIFS(Media_Cliente_Mes!$H$2:$H$145,Media_Cliente_Mes!$A$2:$A$145,$C$21,Media_Cliente_Mes!$B$2:$B$145,$A21),0) -> 43330.53 | D27: =IFERROR(SUMIFS(Media_Cliente_Mes!$H$2:$H$145,Media_Cliente_Mes!$A$2:$A$145,$D$21,Media_Cliente_Mes!$B$2:$B$145,$A21),0) -> 7362.99 | E27: =IFERROR(SUMIFS(Media_Cliente_Mes!$H$2:$H$145,Media_Cliente_Mes!$A$2:$A$145,$E$21,Media_Cliente_Mes!$B$2:$B$145,$A21),0) -> 22201.52 | F27: =IFERROR(SUMIFS(Media_Cliente_Mes!$H$2:$H$145,Media_Cliente_Mes!$A$2:$A$145,$F$21,Media_Cliente_Mes!$B$2:$B$145,$A21),0) -> 0 | G27: =IFERROR(SUMIFS(Media_Cliente_Mes!$H$2:$H$145,Media_Cliente_Mes!$A$2:$A$145,$G$21,Media_Cliente_Mes!$B$2:$B$145,$A21),0) -> 1340.51 | H27: =IFERROR(SUMIFS(Media_Cliente_Mes!$H$2:$H$145,Media_Cliente_Mes!$A$2:$A$145,$H$21,Media_Cliente_Mes!$B$2:$B$145,$A21),0) -> 0 | I27: =IFERROR(SUMIFS(Media_Cliente_Mes!$H$2:$H$145,Media_Cliente_Mes!$A$2:$A$145,$I$21,Media_Cliente_Mes!$B$2:$B$145,$A21),0) -> 0 | J27: =IFERROR(SUMIFS(Media_Cliente_Mes!$H$2:$H$145,Media_Cliente_Mes!$A$2:$A$145,$J$21,Media_Cliente_Mes!$B$2:$B$145,$A21),0) -> 0 | K27: =IFERROR(SUMIFS(Media_Cliente_Mes!$H$2:$H$145,Media_Cliente_Mes!$A$2:$A$145,$K$21,Media_Cliente_Mes!$B$2:$B$145,$A21),0) -> 0 | L27: =IFERROR(SUMIFS(Media_Cliente_Mes!$H$2:$H$145,Media_Cliente_Mes!$A$2:$A$145,$L$21,Media_Cliente_Mes!$B$2:$B$145,$A21),0) -> 0 | M27: =IFERROR(SUMIFS(Media_Cliente_Mes!$H$2:$H$145,Media_Cliente_Mes!$A$2:$A$145,$M$21,Media_Cliente_Mes!$B$2:$B$145,$A21),0) -> 0 | N27: =SUM(B27:M27) -> 74235.55
A28: Vol. Ferro (t) | B28: =IFERROR(SUMIFS(Media_Cliente_Mes!$I$2:$I$145,Media_Cliente_Mes!$A$2:$A$145,$B$21,Media_Cliente_Mes!$B$2:$B$145,$A21),0) -> 0 | C28: =IFERROR(SUMIFS(Media_Cliente_Mes!$I$2:$I$145,Media_Cliente_Mes!$A$2:$A$145,$C$21,Media_Cliente_Mes!$B$2:$B$145,$A21),0) -> 0 | D28: =IFERROR(SUMIFS(Media_Cliente_Mes!$I$2:$I$145,Media_Cliente_Mes!$A$2:$A$145,$D$21,Media_Cliente_Mes!$B$2:$B$145,$A21),0) -> 4915.32 | E28: =IFERROR(SUMIFS(Media_Cliente_Mes!$I$2:$I$145,Media_Cliente_Mes!$A$2:$A$145,$E$21,Media_Cliente_Mes!$B$2:$B$145,$A21),0) -> 37935.85 | F28: =IFERROR(SUMIFS(Media_Cliente_Mes!$I$2:$I$145,Media_Cliente_Mes!$A$2:$A$145,$F$21,Media_Cliente_Mes!$B$2:$B$145,$A21),0) -> 66365.71 | G28: =IFERROR(SUMIFS(Media_Cliente_Mes!$I$2:$I$145,Media_Cliente_Mes!$A$2:$A$145,$G$21,Media_Cliente_Mes!$B$2:$B$145,$A21),0) -> 57135.23 | H28: =IFERROR(SUMIFS(Media_Cliente_Mes!$I$2:$I$145,Media_Cliente_Mes!$A$2:$A$145,$H$21,Media_Cliente_Mes!$B$2:$B$145,$A21),0) -> 141.56 | I28: =IFERROR(SUMIFS(Media_Cliente_Mes!$I$2:$I$145,Media_Cliente_Mes!$A$2:$A$145,$I$21,Media_Cliente_Mes!$B$2:$B$145,$A21),0) -> 0 | J28: =IFERROR(SUMIFS(Media_Cliente_Mes!$I$2:$I$145,Media_Cliente_Mes!$A$2:$A$145,$J$21,Media_Cliente_Mes!$B$2:$B$145,$A21),0) -> 0 | K28: =IFERROR(SUMIFS(Media_Cliente_Mes!$I$2:$I$145,Media_Cliente_Mes!$A$2:$A$145,$K$21,Media_Cliente_Mes!$B$2:$B$145,$A21),0) -> 0 | L28: =IFERROR(SUMIFS(Media_Cliente_Mes!$I$2:$I$145,Media_Cliente_Mes!$A$2:$A$145,$L$21,Media_Cliente_Mes!$B$2:$B$145,$A21),0) -> 0 | M28: =IFERROR(SUMIFS(Media_Cliente_Mes!$I$2:$I$145,Media_Cliente_Mes!$A$2:$A$145,$M$21,Media_Cliente_Mes!$B$2:$B$145,$A21),0) -> 0 | N28: =SUM(B28:M28) -> 166493.67
A30: Abr | B30: Amaggi | C30: Brejeiro | D30: Caramuru | E30: Cargill | F30: Cofco | G30: 3Tentos | H30: Bunge | I30: ADM | J30: Aliança | K30: Olfar | L30: Novo06 | M30: Novo07 | N30: Media Pool
A31: Volume | B31: =IFERROR(SUMIFS(Media_Cliente_Mes!$C$2:$C$145,Media_Cliente_Mes!$A$2:$A$145,$B$30,Media_Cliente_Mes!$B$2:$B$145,$A30),0) -> 16786.6 | C31: =IFERROR(SUMIFS(Media_Cliente_Mes!$C$2:$C$145,Media_Cliente_Mes!$A$2:$A$145,$C$30,Media_Cliente_Mes!$B$2:$B$145,$A30),0) -> 53319.92 | D31: =IFERROR(SUMIFS(Media_Cliente_Mes!$C$2:$C$145,Media_Cliente_Mes!$A$2:$A$145,$D$30,Media_Cliente_Mes!$B$2:$B$145,$A30),0) -> 42872.69 | E31: =IFERROR(SUMIFS(Media_Cliente_Mes!$C$2:$C$145,Media_Cliente_Mes!$A$2:$A$145,$E$30,Media_Cliente_Mes!$B$2:$B$145,$A30),0) -> 53714.89 | F31: =IFERROR(SUMIFS(Media_Cliente_Mes!$C$2:$C$145,Media_Cliente_Mes!$A$2:$A$145,$F$30,Media_Cliente_Mes!$B$2:$B$145,$A30),0) -> 92764.41 | G31: =IFERROR(SUMIFS(Media_Cliente_Mes!$C$2:$C$145,Media_Cliente_Mes!$A$2:$A$145,$G$30,Media_Cliente_Mes!$B$2:$B$145,$A30),0) -> 88798.66 | H31: =IFERROR(SUMIFS(Media_Cliente_Mes!$C$2:$C$145,Media_Cliente_Mes!$A$2:$A$145,$H$30,Media_Cliente_Mes!$B$2:$B$145,$A30),0) -> 10176.79 | I31: =IFERROR(SUMIFS(Media_Cliente_Mes!$C$2:$C$145,Media_Cliente_Mes!$A$2:$A$145,$I$30,Media_Cliente_Mes!$B$2:$B$145,$A30),0) -> 0 | J31: =IFERROR(SUMIFS(Media_Cliente_Mes!$C$2:$C$145,Media_Cliente_Mes!$A$2:$A$145,$J$30,Media_Cliente_Mes!$B$2:$B$145,$A30),0) -> 0 | K31: =IFERROR(SUMIFS(Media_Cliente_Mes!$C$2:$C$145,Media_Cliente_Mes!$A$2:$A$145,$K$30,Media_Cliente_Mes!$B$2:$B$145,$A30),0) -> 0 | L31: =IFERROR(SUMIFS(Media_Cliente_Mes!$C$2:$C$145,Media_Cliente_Mes!$A$2:$A$145,$L$30,Media_Cliente_Mes!$B$2:$B$145,$A30),0) -> 0 | M31: =IFERROR(SUMIFS(Media_Cliente_Mes!$C$2:$C$145,Media_Cliente_Mes!$A$2:$A$145,$M$30,Media_Cliente_Mes!$B$2:$B$145,$A30),0) -> 0 | N31: =SUM(B31:M31) -> 358433.96
A32: Proteina Bruta (%) | B32: =IFERROR(SUMIFS(Media_Cliente_Mes!$D$2:$D$145,Media_Cliente_Mes!$A$2:$A$145,$B$30,Media_Cliente_Mes!$B$2:$B$145,$A30),0) -> 47.379249 | C32: =IFERROR(SUMIFS(Media_Cliente_Mes!$D$2:$D$145,Media_Cliente_Mes!$A$2:$A$145,$C$30,Media_Cliente_Mes!$B$2:$B$145,$A30),0) -> 47.844875 | D32: =IFERROR(SUMIFS(Media_Cliente_Mes!$D$2:$D$145,Media_Cliente_Mes!$A$2:$A$145,$D$30,Media_Cliente_Mes!$B$2:$B$145,$A30),0) -> 47.537638 | E32: =IFERROR(SUMIFS(Media_Cliente_Mes!$D$2:$D$145,Media_Cliente_Mes!$A$2:$A$145,$E$30,Media_Cliente_Mes!$B$2:$B$145,$A30),0) -> 47.586537 | F32: =IFERROR(SUMIFS(Media_Cliente_Mes!$D$2:$D$145,Media_Cliente_Mes!$A$2:$A$145,$F$30,Media_Cliente_Mes!$B$2:$B$145,$A30),0) -> 47.317298 | G32: =IFERROR(SUMIFS(Media_Cliente_Mes!$D$2:$D$145,Media_Cliente_Mes!$A$2:$A$145,$G$30,Media_Cliente_Mes!$B$2:$B$145,$A30),0) -> 47.601937 | H32: =IFERROR(SUMIFS(Media_Cliente_Mes!$D$2:$D$145,Media_Cliente_Mes!$A$2:$A$145,$H$30,Media_Cliente_Mes!$B$2:$B$145,$A30),0) -> 47.444279 | I32: =IFERROR(SUMIFS(Media_Cliente_Mes!$D$2:$D$145,Media_Cliente_Mes!$A$2:$A$145,$I$30,Media_Cliente_Mes!$B$2:$B$145,$A30),0) -> 0 | J32: =IFERROR(SUMIFS(Media_Cliente_Mes!$D$2:$D$145,Media_Cliente_Mes!$A$2:$A$145,$J$30,Media_Cliente_Mes!$B$2:$B$145,$A30),0) -> 0 | K32: =IFERROR(SUMIFS(Media_Cliente_Mes!$D$2:$D$145,Media_Cliente_Mes!$A$2:$A$145,$K$30,Media_Cliente_Mes!$B$2:$B$145,$A30),0) -> 0 | L32: =IFERROR(SUMIFS(Media_Cliente_Mes!$D$2:$D$145,Media_Cliente_Mes!$A$2:$A$145,$L$30,Media_Cliente_Mes!$B$2:$B$145,$A30),0) -> 0 | M32: =IFERROR(SUMIFS(Media_Cliente_Mes!$D$2:$D$145,Media_Cliente_Mes!$A$2:$A$145,$M$30,Media_Cliente_Mes!$B$2:$B$145,$A30),0) -> 0 | N32: =IFERROR(SUMPRODUCT(B31:M31,B32:M32)/SUM(B31:M31),0) -> 47.539506
A33: Umidade (%) | B33: =IFERROR(SUMIFS(Media_Cliente_Mes!$E$2:$E$145,Media_Cliente_Mes!$A$2:$A$145,$B$30,Media_Cliente_Mes!$B$2:$B$145,$A30),0) -> 12.275257 | C33: =IFERROR(SUMIFS(Media_Cliente_Mes!$E$2:$E$145,Media_Cliente_Mes!$A$2:$A$145,$C$30,Media_Cliente_Mes!$B$2:$B$145,$A30),0) -> 11.643986 | D33: =IFERROR(SUMIFS(Media_Cliente_Mes!$E$2:$E$145,Media_Cliente_Mes!$A$2:$A$145,$D$30,Media_Cliente_Mes!$B$2:$B$145,$A30),0) -> 13.002426 | E33: =IFERROR(SUMIFS(Media_Cliente_Mes!$E$2:$E$145,Media_Cliente_Mes!$A$2:$A$145,$E$30,Media_Cliente_Mes!$B$2:$B$145,$A30),0) -> 12.255133 | F33: =IFERROR(SUMIFS(Media_Cliente_Mes!$E$2:$E$145,Media_Cliente_Mes!$A$2:$A$145,$F$30,Media_Cliente_Mes!$B$2:$B$145,$A30),0) -> 12.448229 | G33: =IFERROR(SUMIFS(Media_Cliente_Mes!$E$2:$E$145,Media_Cliente_Mes!$A$2:$A$145,$G$30,Media_Cliente_Mes!$B$2:$B$145,$A30),0) -> 12.458098 | H33: =IFERROR(SUMIFS(Media_Cliente_Mes!$E$2:$E$145,Media_Cliente_Mes!$A$2:$A$145,$H$30,Media_Cliente_Mes!$B$2:$B$145,$A30),0) -> 12.459751 | I33: =IFERROR(SUMIFS(Media_Cliente_Mes!$E$2:$E$145,Media_Cliente_Mes!$A$2:$A$145,$I$30,Media_Cliente_Mes!$B$2:$B$145,$A30),0) -> 0 | J33: =IFERROR(SUMIFS(Media_Cliente_Mes!$E$2:$E$145,Media_Cliente_Mes!$A$2:$A$145,$J$30,Media_Cliente_Mes!$B$2:$B$145,$A30),0) -> 0 | K33: =IFERROR(SUMIFS(Media_Cliente_Mes!$E$2:$E$145,Media_Cliente_Mes!$A$2:$A$145,$K$30,Media_Cliente_Mes!$B$2:$B$145,$A30),0) -> 0 | L33: =IFERROR(SUMIFS(Media_Cliente_Mes!$E$2:$E$145,Media_Cliente_Mes!$A$2:$A$145,$L$30,Media_Cliente_Mes!$B$2:$B$145,$A30),0) -> 0 | M33: =IFERROR(SUMIFS(Media_Cliente_Mes!$E$2:$E$145,Media_Cliente_Mes!$A$2:$A$145,$M$30,Media_Cliente_Mes!$B$2:$B$145,$A30),0) -> 0 | N33: =IFERROR(SUMPRODUCT(B31:M31,B33:M33)/SUM(B31:M31),0) -> 12.360613
A34: Fibra (%) | B34: =IFERROR(SUMIFS(Media_Cliente_Mes!$F$2:$F$145,Media_Cliente_Mes!$A$2:$A$145,$B$30,Media_Cliente_Mes!$B$2:$B$145,$A30),0) -> 3.75 | C34: =IFERROR(SUMIFS(Media_Cliente_Mes!$F$2:$F$145,Media_Cliente_Mes!$A$2:$A$145,$C$30,Media_Cliente_Mes!$B$2:$B$145,$A30),0) -> 3.5823332 | D34: =IFERROR(SUMIFS(Media_Cliente_Mes!$F$2:$F$145,Media_Cliente_Mes!$A$2:$A$145,$D$30,Media_Cliente_Mes!$B$2:$B$145,$A30),0) -> 3.6055045 | E34: =IFERROR(SUMIFS(Media_Cliente_Mes!$F$2:$F$145,Media_Cliente_Mes!$A$2:$A$145,$E$30,Media_Cliente_Mes!$B$2:$B$145,$A30),0) -> 3.6579165 | F34: =IFERROR(SUMIFS(Media_Cliente_Mes!$F$2:$F$145,Media_Cliente_Mes!$A$2:$A$145,$F$30,Media_Cliente_Mes!$B$2:$B$145,$A30),0) -> 3.7610284 | G34: =IFERROR(SUMIFS(Media_Cliente_Mes!$F$2:$F$145,Media_Cliente_Mes!$A$2:$A$145,$G$30,Media_Cliente_Mes!$B$2:$B$145,$A30),0) -> 3.6137118 | H34: =IFERROR(SUMIFS(Media_Cliente_Mes!$F$2:$F$145,Media_Cliente_Mes!$A$2:$A$145,$H$30,Media_Cliente_Mes!$B$2:$B$145,$A30),0) -> 3.6968507 | I34: =IFERROR(SUMIFS(Media_Cliente_Mes!$F$2:$F$145,Media_Cliente_Mes!$A$2:$A$145,$I$30,Media_Cliente_Mes!$B$2:$B$145,$A30),0) -> 0 | J34: =IFERROR(SUMIFS(Media_Cliente_Mes!$F$2:$F$145,Media_Cliente_Mes!$A$2:$A$145,$J$30,Media_Cliente_Mes!$B$2:$B$145,$A30),0) -> 0 | K34: =IFERROR(SUMIFS(Media_Cliente_Mes!$F$2:$F$145,Media_Cliente_Mes!$A$2:$A$145,$K$30,Media_Cliente_Mes!$B$2:$B$145,$A30),0) -> 0 | L34: =IFERROR(SUMIFS(Media_Cliente_Mes!$F$2:$F$145,Media_Cliente_Mes!$A$2:$A$145,$L$30,Media_Cliente_Mes!$B$2:$B$145,$A30),0) -> 0 | M34: =IFERROR(SUMIFS(Media_Cliente_Mes!$F$2:$F$145,Media_Cliente_Mes!$A$2:$A$145,$M$30,Media_Cliente_Mes!$B$2:$B$145,$A30),0) -> 0 | N34: =IFERROR(SUMPRODUCT(B31:M31,B34:M34)/SUM(B31:M31),0) -> 3.6615564
A35: Oleo (%) | B35: =IFERROR(SUMIFS(Media_Cliente_Mes!$G$2:$G$145,Media_Cliente_Mes!$A$2:$A$145,$B$30,Media_Cliente_Mes!$B$2:$B$145,$A30),0) -> 1.6382478 | C35: =IFERROR(SUMIFS(Media_Cliente_Mes!$G$2:$G$145,Media_Cliente_Mes!$A$2:$A$145,$C$30,Media_Cliente_Mes!$B$2:$B$145,$A30),0) -> 1.3625796 | D35: =IFERROR(SUMIFS(Media_Cliente_Mes!$G$2:$G$145,Media_Cliente_Mes!$A$2:$A$145,$D$30,Media_Cliente_Mes!$B$2:$B$145,$A30),0) -> 1.2921132 | E35: =IFERROR(SUMIFS(Media_Cliente_Mes!$G$2:$G$145,Media_Cliente_Mes!$A$2:$A$145,$E$30,Media_Cliente_Mes!$B$2:$B$145,$A30),0) -> 1.7030581 | F35: =IFERROR(SUMIFS(Media_Cliente_Mes!$G$2:$G$145,Media_Cliente_Mes!$A$2:$A$145,$F$30,Media_Cliente_Mes!$B$2:$B$145,$A30),0) -> 1.5124015 | G35: =IFERROR(SUMIFS(Media_Cliente_Mes!$G$2:$G$145,Media_Cliente_Mes!$A$2:$A$145,$G$30,Media_Cliente_Mes!$B$2:$B$145,$A30),0) -> 1.6334797 | H35: =IFERROR(SUMIFS(Media_Cliente_Mes!$G$2:$G$145,Media_Cliente_Mes!$A$2:$A$145,$H$30,Media_Cliente_Mes!$B$2:$B$145,$A30),0) -> 1.8427868 | I35: =IFERROR(SUMIFS(Media_Cliente_Mes!$G$2:$G$145,Media_Cliente_Mes!$A$2:$A$145,$I$30,Media_Cliente_Mes!$B$2:$B$145,$A30),0) -> 0 | J35: =IFERROR(SUMIFS(Media_Cliente_Mes!$G$2:$G$145,Media_Cliente_Mes!$A$2:$A$145,$J$30,Media_Cliente_Mes!$B$2:$B$145,$A30),0) -> 0 | K35: =IFERROR(SUMIFS(Media_Cliente_Mes!$G$2:$G$145,Media_Cliente_Mes!$A$2:$A$145,$K$30,Media_Cliente_Mes!$B$2:$B$145,$A30),0) -> 0 | L35: =IFERROR(SUMIFS(Media_Cliente_Mes!$G$2:$G$145,Media_Cliente_Mes!$A$2:$A$145,$L$30,Media_Cliente_Mes!$B$2:$B$145,$A30),0) -> 0 | M35: =IFERROR(SUMIFS(Media_Cliente_Mes!$G$2:$G$145,Media_Cliente_Mes!$A$2:$A$145,$M$30,Media_Cliente_Mes!$B$2:$B$145,$A30),0) -> 0 | N35: =IFERROR(SUMPRODUCT(B31:M31,B35:M35)/SUM(B31:M31),0) -> 1.5376073
A36: Vol. Rodo (t) | B36: =IFERROR(SUMIFS(Media_Cliente_Mes!$H$2:$H$145,Media_Cliente_Mes!$A$2:$A$145,$B$30,Media_Cliente_Mes!$B$2:$B$145,$A30),0) -> 0 | C36: =IFERROR(SUMIFS(Media_Cliente_Mes!$H$2:$H$145,Media_Cliente_Mes!$A$2:$A$145,$C$30,Media_Cliente_Mes!$B$2:$B$145,$A30),0) -> 53319.92 | D36: =IFERROR(SUMIFS(Media_Cliente_Mes!$H$2:$H$145,Media_Cliente_Mes!$A$2:$A$145,$D$30,Media_Cliente_Mes!$B$2:$B$145,$A30),0) -> 9022.05 | E36: =IFERROR(SUMIFS(Media_Cliente_Mes!$H$2:$H$145,Media_Cliente_Mes!$A$2:$A$145,$E$30,Media_Cliente_Mes!$B$2:$B$145,$A30),0) -> 31236.13 | F36: =IFERROR(SUMIFS(Media_Cliente_Mes!$H$2:$H$145,Media_Cliente_Mes!$A$2:$A$145,$F$30,Media_Cliente_Mes!$B$2:$B$145,$A30),0) -> 0 | G36: =IFERROR(SUMIFS(Media_Cliente_Mes!$H$2:$H$145,Media_Cliente_Mes!$A$2:$A$145,$G$30,Media_Cliente_Mes!$B$2:$B$145,$A30),0) -> 28630.42 | H36: =IFERROR(SUMIFS(Media_Cliente_Mes!$H$2:$H$145,Media_Cliente_Mes!$A$2:$A$145,$H$30,Media_Cliente_Mes!$B$2:$B$145,$A30),0) -> 0 | I36: =IFERROR(SUMIFS(Media_Cliente_Mes!$H$2:$H$145,Media_Cliente_Mes!$A$2:$A$145,$I$30,Media_Cliente_Mes!$B$2:$B$145,$A30),0) -> 0 | J36: =IFERROR(SUMIFS(Media_Cliente_Mes!$H$2:$H$145,Media_Cliente_Mes!$A$2:$A$145,$J$30,Media_Cliente_Mes!$B$2:$B$145,$A30),0) -> 0 | K36: =IFERROR(SUMIFS(Media_Cliente_Mes!$H$2:$H$145,Media_Cliente_Mes!$A$2:$A$145,$K$30,Media_Cliente_Mes!$B$2:$B$145,$A30),0) -> 0 | L36: =IFERROR(SUMIFS(Media_Cliente_Mes!$H$2:$H$145,Media_Cliente_Mes!$A$2:$A$145,$L$30,Media_Cliente_Mes!$B$2:$B$145,$A30),0) -> 0 | M36: =IFERROR(SUMIFS(Media_Cliente_Mes!$H$2:$H$145,Media_Cliente_Mes!$A$2:$A$145,$M$30,Media_Cliente_Mes!$B$2:$B$145,$A30),0) -> 0 | N36: =SUM(B36:M36) -> 122208.52
A37: Vol. Ferro (t) | B37: =IFERROR(SUMIFS(Media_Cliente_Mes!$I$2:$I$145,Media_Cliente_Mes!$A$2:$A$145,$B$30,Media_Cliente_Mes!$B$2:$B$145,$A30),0) -> 16786.6 | C37: =IFERROR(SUMIFS(Media_Cliente_Mes!$I$2:$I$145,Media_Cliente_Mes!$A$2:$A$145,$C$30,Media_Cliente_Mes!$B$2:$B$145,$A30),0) -> 0 | D37: =IFERROR(SUMIFS(Media_Cliente_Mes!$I$2:$I$145,Media_Cliente_Mes!$A$2:$A$145,$D$30,Media_Cliente_Mes!$B$2:$B$145,$A30),0) -> 33850.64 | E37: =IFERROR(SUMIFS(Media_Cliente_Mes!$I$2:$I$145,Media_Cliente_Mes!$A$2:$A$145,$E$30,Media_Cliente_Mes!$B$2:$B$145,$A30),0) -> 22478.76 | F37: =IFERROR(SUMIFS(Media_Cliente_Mes!$I$2:$I$145,Media_Cliente_Mes!$A$2:$A$145,$F$30,Media_Cliente_Mes!$B$2:$B$145,$A30),0) -> 92764.41 | G37: =IFERROR(SUMIFS(Media_Cliente_Mes!$I$2:$I$145,Media_Cliente_Mes!$A$2:$A$145,$G$30,Media_Cliente_Mes!$B$2:$B$145,$A30),0) -> 60168.24 | H37: =IFERROR(SUMIFS(Media_Cliente_Mes!$I$2:$I$145,Media_Cliente_Mes!$A$2:$A$145,$H$30,Media_Cliente_Mes!$B$2:$B$145,$A30),0) -> 10176.79 | I37: =IFERROR(SUMIFS(Media_Cliente_Mes!$I$2:$I$145,Media_Cliente_Mes!$A$2:$A$145,$I$30,Media_Cliente_Mes!$B$2:$B$145,$A30),0) -> 0 | J37: =IFERROR(SUMIFS(Media_Cliente_Mes!$I$2:$I$145,Media_Cliente_Mes!$A$2:$A$145,$J$30,Media_Cliente_Mes!$B$2:$B$145,$A30),0) -> 0 | K37: =IFERROR(SUMIFS(Media_Cliente_Mes!$I$2:$I$145,Media_Cliente_Mes!$A$2:$A$145,$K$30,Media_Cliente_Mes!$B$2:$B$145,$A30),0) -> 0 | L37: =IFERROR(SUMIFS(Media_Cliente_Mes!$I$2:$I$145,Media_Cliente_Mes!$A$2:$A$145,$L$30,Media_Cliente_Mes!$B$2:$B$145,$A30),0) -> 0 | M37: =IFERROR(SUMIFS(Media_Cliente_Mes!$I$2:$I$145,Media_Cliente_Mes!$A$2:$A$145,$M$30,Media_Cliente_Mes!$B$2:$B$145,$A30),0) -> 0 | N37: =SUM(B37:M37) -> 236225.44
A39: Mai | B39: Amaggi | C39: Brejeiro | D39: Caramuru | E39: Cargill | F39: Cofco | G39: 3Tentos | H39: Bunge | I39: ADM | J39: Aliança | K39: Olfar | L39: Novo06 | M39: Novo07 | N39: Media Pool
A40: Volume | B40: =IFERROR(SUMIFS(Media_Cliente_Mes!$C$2:$C$145,Media_Cliente_Mes!$A$2:$A$145,$B$39,Media_Cliente_Mes!$B$2:$B$145,$A39),0) -> 43820.37 | C40: =IFERROR(SUMIFS(Media_Cliente_Mes!$C$2:$C$145,Media_Cliente_Mes!$A$2:$A$145,$C$39,Media_Cliente_Mes!$B$2:$B$145,$A39),0) -> 49598.12 | D40: =IFERROR(SUMIFS(Media_Cliente_Mes!$C$2:$C$145,Media_Cliente_Mes!$A$2:$A$145,$D$39,Media_Cliente_Mes!$B$2:$B$145,$A39),0) -> 17619.63 | E40: =IFERROR(SUMIFS(Media_Cliente_Mes!$C$2:$C$145,Media_Cliente_Mes!$A$2:$A$145,$E$39,Media_Cliente_Mes!$B$2:$B$145,$A39),0) -> 53120.9 | F40: =IFERROR(SUMIFS(Media_Cliente_Mes!$C$2:$C$145,Media_Cliente_Mes!$A$2:$A$145,$F$39,Media_Cliente_Mes!$B$2:$B$145,$A39),0) -> 63744.72 | G40: =IFERROR(SUMIFS(Media_Cliente_Mes!$C$2:$C$145,Media_Cliente_Mes!$A$2:$A$145,$G$39,Media_Cliente_Mes!$B$2:$B$145,$A39),0) -> 62604.74 | H40: =IFERROR(SUMIFS(Media_Cliente_Mes!$C$2:$C$145,Media_Cliente_Mes!$A$2:$A$145,$H$39,Media_Cliente_Mes!$B$2:$B$145,$A39),0) -> 0 | I40: =IFERROR(SUMIFS(Media_Cliente_Mes!$C$2:$C$145,Media_Cliente_Mes!$A$2:$A$145,$I$39,Media_Cliente_Mes!$B$2:$B$145,$A39),0) -> 0 | J40: =IFERROR(SUMIFS(Media_Cliente_Mes!$C$2:$C$145,Media_Cliente_Mes!$A$2:$A$145,$J$39,Media_Cliente_Mes!$B$2:$B$145,$A39),0) -> 0 | K40: =IFERROR(SUMIFS(Media_Cliente_Mes!$C$2:$C$145,Media_Cliente_Mes!$A$2:$A$145,$K$39,Media_Cliente_Mes!$B$2:$B$145,$A39),0) -> 0 | L40: =IFERROR(SUMIFS(Media_Cliente_Mes!$C$2:$C$145,Media_Cliente_Mes!$A$2:$A$145,$L$39,Media_Cliente_Mes!$B$2:$B$145,$A39),0) -> 0 | M40: =IFERROR(SUMIFS(Media_Cliente_Mes!$C$2:$C$145,Media_Cliente_Mes!$A$2:$A$145,$M$39,Media_Cliente_Mes!$B$2:$B$145,$A39),0) -> 0 | N40: =SUM(B40:M40) -> 290508.48
A41: Proteina Bruta (%) | B41: =IFERROR(SUMIFS(Media_Cliente_Mes!$D$2:$D$145,Media_Cliente_Mes!$A$2:$A$145,$B$39,Media_Cliente_Mes!$B$2:$B$145,$A39),0) -> 47.583075 | C41: =IFERROR(SUMIFS(Media_Cliente_Mes!$D$2:$D$145,Media_Cliente_Mes!$A$2:$A$145,$C$39,Media_Cliente_Mes!$B$2:$B$145,$A39),0) -> 48.05034 | D41: =IFERROR(SUMIFS(Media_Cliente_Mes!$D$2:$D$145,Media_Cliente_Mes!$A$2:$A$145,$D$39,Media_Cliente_Mes!$B$2:$B$145,$A39),0) -> 47.450584 | E41: =IFERROR(SUMIFS(Media_Cliente_Mes!$D$2:$D$145,Media_Cliente_Mes!$A$2:$A$145,$E$39,Media_Cliente_Mes!$B$2:$B$145,$A39),0) -> 47.449685 | F41: =IFERROR(SUMIFS(Media_Cliente_Mes!$D$2:$D$145,Media_Cliente_Mes!$A$2:$A$145,$F$39,Media_Cliente_Mes!$B$2:$B$145,$A39),0) -> 47.685834 | G41: =IFERROR(SUMIFS(Media_Cliente_Mes!$D$2:$D$145,Media_Cliente_Mes!$A$2:$A$145,$G$39,Media_Cliente_Mes!$B$2:$B$145,$A39),0) -> 47.492541 | H41: =IFERROR(SUMIFS(Media_Cliente_Mes!$D$2:$D$145,Media_Cliente_Mes!$A$2:$A$145,$H$39,Media_Cliente_Mes!$B$2:$B$145,$A39),0) -> 0 | I41: =IFERROR(SUMIFS(Media_Cliente_Mes!$D$2:$D$145,Media_Cliente_Mes!$A$2:$A$145,$I$39,Media_Cliente_Mes!$B$2:$B$145,$A39),0) -> 0 | J41: =IFERROR(SUMIFS(Media_Cliente_Mes!$D$2:$D$145,Media_Cliente_Mes!$A$2:$A$145,$J$39,Media_Cliente_Mes!$B$2:$B$145,$A39),0) -> 0 | K41: =IFERROR(SUMIFS(Media_Cliente_Mes!$D$2:$D$145,Media_Cliente_Mes!$A$2:$A$145,$K$39,Media_Cliente_Mes!$B$2:$B$145,$A39),0) -> 0 | L41: =IFERROR(SUMIFS(Media_Cliente_Mes!$D$2:$D$145,Media_Cliente_Mes!$A$2:$A$145,$L$39,Media_Cliente_Mes!$B$2:$B$145,$A39),0) -> 0 | M41: =IFERROR(SUMIFS(Media_Cliente_Mes!$D$2:$D$145,Media_Cliente_Mes!$A$2:$A$145,$M$39,Media_Cliente_Mes!$B$2:$B$145,$A39),0) -> 0 | N41: =IFERROR(SUMPRODUCT(B40:M40,B41:M41)/SUM(B40:M40),0) -> 47.633461
A42: Umidade (%) | B42: =IFERROR(SUMIFS(Media_Cliente_Mes!$E$2:$E$145,Media_Cliente_Mes!$A$2:$A$145,$B$39,Media_Cliente_Mes!$B$2:$B$145,$A39),0) -> 12.388954 | C42: =IFERROR(SUMIFS(Media_Cliente_Mes!$E$2:$E$145,Media_Cliente_Mes!$A$2:$A$145,$C$39,Media_Cliente_Mes!$B$2:$B$145,$A39),0) -> 11.668975 | D42: =IFERROR(SUMIFS(Media_Cliente_Mes!$E$2:$E$145,Media_Cliente_Mes!$A$2:$A$145,$D$39,Media_Cliente_Mes!$B$2:$B$145,$A39),0) -> 12.782202 | E42: =IFERROR(SUMIFS(Media_Cliente_Mes!$E$2:$E$145,Media_Cliente_Mes!$A$2:$A$145,$E$39,Media_Cliente_Mes!$B$2:$B$145,$A39),0) -> 12.356194 | F42: =IFERROR(SUMIFS(Media_Cliente_Mes!$E$2:$E$145,Media_Cliente_Mes!$A$2:$A$145,$F$39,Media_Cliente_Mes!$B$2:$B$145,$A39),0) -> 12.507504 | G42: =IFERROR(SUMIFS(Media_Cliente_Mes!$E$2:$E$145,Media_Cliente_Mes!$A$2:$A$145,$G$39,Media_Cliente_Mes!$B$2:$B$145,$A39),0) -> 12.399482 | H42: =IFERROR(SUMIFS(Media_Cliente_Mes!$E$2:$E$145,Media_Cliente_Mes!$A$2:$A$145,$H$39,Media_Cliente_Mes!$B$2:$B$145,$A39),0) -> 0 | I42: =IFERROR(SUMIFS(Media_Cliente_Mes!$E$2:$E$145,Media_Cliente_Mes!$A$2:$A$145,$I$39,Media_Cliente_Mes!$B$2:$B$145,$A39),0) -> 0 | J42: =IFERROR(SUMIFS(Media_Cliente_Mes!$E$2:$E$145,Media_Cliente_Mes!$A$2:$A$145,$J$39,Media_Cliente_Mes!$B$2:$B$145,$A39),0) -> 0 | K42: =IFERROR(SUMIFS(Media_Cliente_Mes!$E$2:$E$145,Media_Cliente_Mes!$A$2:$A$145,$K$39,Media_Cliente_Mes!$B$2:$B$145,$A39),0) -> 0 | L42: =IFERROR(SUMIFS(Media_Cliente_Mes!$E$2:$E$145,Media_Cliente_Mes!$A$2:$A$145,$L$39,Media_Cliente_Mes!$B$2:$B$145,$A39),0) -> 0 | M42: =IFERROR(SUMIFS(Media_Cliente_Mes!$E$2:$E$145,Media_Cliente_Mes!$A$2:$A$145,$M$39,Media_Cliente_Mes!$B$2:$B$145,$A39),0) -> 0 | N42: =IFERROR(SUMPRODUCT(B40:M40,B42:M42)/SUM(B40:M40),0) -> 12.312175
A43: Fibra (%) | B43: =IFERROR(SUMIFS(Media_Cliente_Mes!$F$2:$F$145,Media_Cliente_Mes!$A$2:$A$145,$B$39,Media_Cliente_Mes!$B$2:$B$145,$A39),0) -> 3.637719 | C43: =IFERROR(SUMIFS(Media_Cliente_Mes!$F$2:$F$145,Media_Cliente_Mes!$A$2:$A$145,$C$39,Media_Cliente_Mes!$B$2:$B$145,$A39),0) -> 3.5101214 | D43: =IFERROR(SUMIFS(Media_Cliente_Mes!$F$2:$F$145,Media_Cliente_Mes!$A$2:$A$145,$D$39,Media_Cliente_Mes!$B$2:$B$145,$A39),0) -> 3.6971621 | E43: =IFERROR(SUMIFS(Media_Cliente_Mes!$F$2:$F$145,Media_Cliente_Mes!$A$2:$A$145,$E$39,Media_Cliente_Mes!$B$2:$B$145,$A39),0) -> 3.6931851 | F43: =IFERROR(SUMIFS(Media_Cliente_Mes!$F$2:$F$145,Media_Cliente_Mes!$A$2:$A$145,$F$39,Media_Cliente_Mes!$B$2:$B$145,$A39),0) -> 3.5971201 | G43: =IFERROR(SUMIFS(Media_Cliente_Mes!$F$2:$F$145,Media_Cliente_Mes!$A$2:$A$145,$G$39,Media_Cliente_Mes!$B$2:$B$145,$A39),0) -> 3.7512945 | H43: =IFERROR(SUMIFS(Media_Cliente_Mes!$F$2:$F$145,Media_Cliente_Mes!$A$2:$A$145,$H$39,Media_Cliente_Mes!$B$2:$B$145,$A39),0) -> 0 | I43: =IFERROR(SUMIFS(Media_Cliente_Mes!$F$2:$F$145,Media_Cliente_Mes!$A$2:$A$145,$I$39,Media_Cliente_Mes!$B$2:$B$145,$A39),0) -> 0 | J43: =IFERROR(SUMIFS(Media_Cliente_Mes!$F$2:$F$145,Media_Cliente_Mes!$A$2:$A$145,$J$39,Media_Cliente_Mes!$B$2:$B$145,$A39),0) -> 0 | K43: =IFERROR(SUMIFS(Media_Cliente_Mes!$F$2:$F$145,Media_Cliente_Mes!$A$2:$A$145,$K$39,Media_Cliente_Mes!$B$2:$B$145,$A39),0) -> 0 | L43: =IFERROR(SUMIFS(Media_Cliente_Mes!$F$2:$F$145,Media_Cliente_Mes!$A$2:$A$145,$L$39,Media_Cliente_Mes!$B$2:$B$145,$A39),0) -> 0 | M43: =IFERROR(SUMIFS(Media_Cliente_Mes!$F$2:$F$145,Media_Cliente_Mes!$A$2:$A$145,$M$39,Media_Cliente_Mes!$B$2:$B$145,$A39),0) -> 0 | N43: =IFERROR(SUMPRODUCT(B40:M40,B43:M43)/SUM(B40:M40),0) -> 3.6452492
A44: Oleo (%) | B44: =IFERROR(SUMIFS(Media_Cliente_Mes!$G$2:$G$145,Media_Cliente_Mes!$A$2:$A$145,$B$39,Media_Cliente_Mes!$B$2:$B$145,$A39),0) -> 1.7407996 | C44: =IFERROR(SUMIFS(Media_Cliente_Mes!$G$2:$G$145,Media_Cliente_Mes!$A$2:$A$145,$C$39,Media_Cliente_Mes!$B$2:$B$145,$A39),0) -> 1.0572907 | D44: =IFERROR(SUMIFS(Media_Cliente_Mes!$G$2:$G$145,Media_Cliente_Mes!$A$2:$A$145,$D$39,Media_Cliente_Mes!$B$2:$B$145,$A39),0) -> 1.3727063 | E44: =IFERROR(SUMIFS(Media_Cliente_Mes!$G$2:$G$145,Media_Cliente_Mes!$A$2:$A$145,$E$39,Media_Cliente_Mes!$B$2:$B$145,$A39),0) -> 1.5663225 | F44: =IFERROR(SUMIFS(Media_Cliente_Mes!$G$2:$G$145,Media_Cliente_Mes!$A$2:$A$145,$F$39,Media_Cliente_Mes!$B$2:$B$145,$A39),0) -> 1.5129967 | G44: =IFERROR(SUMIFS(Media_Cliente_Mes!$G$2:$G$145,Media_Cliente_Mes!$A$2:$A$145,$G$39,Media_Cliente_Mes!$B$2:$B$145,$A39),0) -> 1.6846141 | H44: =IFERROR(SUMIFS(Media_Cliente_Mes!$G$2:$G$145,Media_Cliente_Mes!$A$2:$A$145,$H$39,Media_Cliente_Mes!$B$2:$B$145,$A39),0) -> 0 | I44: =IFERROR(SUMIFS(Media_Cliente_Mes!$G$2:$G$145,Media_Cliente_Mes!$A$2:$A$145,$I$39,Media_Cliente_Mes!$B$2:$B$145,$A39),0) -> 0 | J44: =IFERROR(SUMIFS(Media_Cliente_Mes!$G$2:$G$145,Media_Cliente_Mes!$A$2:$A$145,$J$39,Media_Cliente_Mes!$B$2:$B$145,$A39),0) -> 0 | K44: =IFERROR(SUMIFS(Media_Cliente_Mes!$G$2:$G$145,Media_Cliente_Mes!$A$2:$A$145,$K$39,Media_Cliente_Mes!$B$2:$B$145,$A39),0) -> 0 | L44: =IFERROR(SUMIFS(Media_Cliente_Mes!$G$2:$G$145,Media_Cliente_Mes!$A$2:$A$145,$L$39,Media_Cliente_Mes!$B$2:$B$145,$A39),0) -> 0 | M44: =IFERROR(SUMIFS(Media_Cliente_Mes!$G$2:$G$145,Media_Cliente_Mes!$A$2:$A$145,$M$39,Media_Cliente_Mes!$B$2:$B$145,$A39),0) -> 0 | N44: =IFERROR(SUMPRODUCT(B40:M40,B44:M44)/SUM(B40:M40),0) -> 1.5077822
